Workbook

Sheet Case Study
B2: # | C2: Trade/ Transaction details | D2: Currency | E2: Notional /Amount | F2: Trade date | G2: Maturity/ Expiry | H2: Strike/Rate/ other input | I2: Counterparty
B3: 1 | C3: Bank buys a forward on the S&P 500 Index at a forward level of $5250. Current S& P 500 level is $5100 | D3: USD | E3: $25 million | F3: 46262 | G3: 46627 | H3: Forward level :$ 5250 | I3: Bank A
B4: 2 | C4: Bank buys a 1 year call option on the S&P 500 index. The index is currently at $5000 and the bank pays a premium for the option | D4: USD | E4: $10 million | F4: 46262 | G4: 46627 | H4: Strike: $5200; current index: $5000 | I4: Bank B
B5: 3 | C5: Bank buys a 6 month put option on the Euro Stoxx 50 index to protect againts a fall in the equity index | D5: EUR | E5: EUR 12 million | F5: 46262 | G5: 46446 | H5: Strike : EUR 5000; Current Index: EUR 5250 | I5: Bank C
B6: 4 | C6: Bank receives the total return of the S&P 500 Index and pays a financing rate to the conterparty for the duration of the transaction | D6: USD | E6: $30 million | F6: 46262 | G6: 47358 | H6: Financing ; SOFR + 1.20% | I6: Bank D
B7: 5 | C7: Bank buys a NASDAQ 100 index future. The current index level is $22000 and the agreed futures price is $22150 | D7: USD | E7: $20 million | F7: 46262 | G7: 46374 | H7: Futures level : $22150 | I7: Bank E
B8: 6 | C8: Bank buys EUR and sells USD under a 1 year forward contract | D8: EUR | E8: EUR 15 million | F8: 46262 | G8: 46627 | H8: Forward rate : 1.1900 EUR/USD; Spot : 1.1750 | I8: Bank F
B9: 7 | C9: Bank buys a EUR/USD call option, giving it the right to buy EUR against USD | D9: EUR | E9: EUR 10 million | F9: 46262 | G9: 46446 | H9: Strike : 1.1800; Spot : 1.1750 | I9: Bank G
B10: 8 | C10: Bank buys a USD/JPY put option, giving it the right to sell USD against JPY | D10: USD | E10: $8 million | F10: 46262 | G10: 46627 | H10: Strike: 145.00; Spot : 148.00 | I10: Bank H
B11: 9 | C11: Bank enters into a cross-currency swap, paying USD interest and receiving EUR interest over the life of the transaction | D11: USD | E11: $40 million | F11: 46262 | G11: 48088 | H11: USD rate : SOFR + 1.00%; EUR rate : STR + 0.8% | I11: Bank I
B12: 10 | C12: Bank enters into a 6 month EUR/USD FX swap, exchanging EUR and USD initially and reversing the exchange at maturity. | D12: EUR | E12: EUR 20 million | F12: 46262 | G12: 46446 | H12: Spot : 1.1750; Forward points : +35 pips | I12: Bank J
B13: 11 | C13: Bank agrees to buy Brent crude oil under a 1 year forward contract at a fixed price | D13: USD | E13: $12 million | F13: 46262 | G13: 46627 | H13: Forward price: $78/ barrel; current price: $70/barrel | I13: Bank K
B14: 12 | C14: Bank enters into a WTI crude oil futures contract to purchase crude oil at a predetermined futures price | D14: USD | E14: $12 million | F14: 46262 | G14: 46346 | H14: Futures price : $72/barrel; current prices: $70/barrel | I14: Bank L
... B21: 19 | C21: Bank buys a 3-Year SOFR cap, providing protection if SOFR rises above the agreed strike rate | D21: USD | E21: $20 million | F21: 46262 | G21: 47358 | H21: Cap Strike: 4.50%; Current SOFR: 3.80% | I21: Bank S
B22: 20 | C22: Bank enters into a 6 x 9 USD FRA, fixing the interest rate for a 3 month borrowing period beginning in 6 months | D22: USD | E22: $15 million | F22: 46262 | G22: Starts : 28-02-2027 Ends : 28-05-2027 | H22: FRA rate: 4.10%; Current reference: 3.85% | I22: Bank T
B23: 21 | C23: Bank buys Credit protection on a single name corporate borrower for 5 years. The bank pays a premium and receives protection if a credit event occurs | D23: USD | E23: $10 million | F23: 46262 | G23: 48088 | H23: CDS spread : 125 bps; Recovery : 40% | I23: Bank U
B24: 22 | C24: Bank buys protection on the CDS investment grade index for 5 years | D24: USD | E24: $20 million | F24: 46262 | G24: 48088 | H24: CDS index spread : 65 bps; Recovery : 40% | I24: Bank V
B25: 23 | C25: Bank buys a call option on a CDS index, giving it the right to enter into a CDS index protection at a predetermined spread | D25: USD | E25: $12 million | F25: 46262 | G25: 46446 | H25: Strike Spread : 70 bps; current spread : 65 bps | I25: Bank W
B26: 24 | C26: Bank enters into a forward contract on a corporate credit spread, agreeing today on a spread level thet will apply at a future date | D26: USD | E26: $8 million | F26: 46262 | G26: 46627 | H26: Forward spread : 150 bps current Spread : 135 bps | I26: Bank X

Sheet Trades Inputs
A1: # | B1: Trade/Transaction Details | C1: Trade Identification | D1: Product Type | E1: Position | F1: Underlying/Reference | G1: Trade date | H1: Maturity/Expiry | I1: Settlement Type | J1: Counterparty | K1: Buy Currency | L1: Sell Currency | M1: Currency | N1: Buy Notional | O1: Sell Notional | P1: Trade Notional | Q1: Calculation Currency | R1: Spot price | S1: Forward/Futures | T1: Strike | U1: Fixed rate | V1: Floating rate / Index | W1: Forward points | X1: Rate Index | Y1: Sub-Curve | Z1: Tenor | AA1: Reset Frequency | AB1: Payment Frequency | AC1: FX Currency pair | AD1: FX Volatility Group | AE1: FX Option Maturity | AF1: Equity/Index Name | AG1: Equity Bucket | AH1: Sector (Equity) | AI1: Market Capitalization | AJ1: Commodity Type | AK1: Commodity Location/Grade | AL1: Commodity Bucket | AM1: Commodity Tenor | AN1: Commodity Unit | AO1: Commodity Quantity | AP1: Credit Reference Entity | AQ1: Credit rating | AR1: Credit Bucket | AS1: Seniority | AT1: Credit Tenor | AU1: Option Type | AV1: Call/Put | AW1: Exercise Style | AX1: Strike (Option) | AY1: Expiry (Option) | AZ1: Underlying Price | BA1: Volatility | BB1: SIMM Risk Class | BC1: SIMM Bucket | BD1: SIMM Risk Factor | BE1: SIMM Sub-bucket/Category | BF1: Region | BG1: Sector (SIMM) | BH1: Sensitivity currency | BI1: Risk Factor Tenor | BJ1: Sensitivity date/Expiry | BK1: Collateral/Margin Agreement | BL1: Netting Set | BM1: Counterparty (Other) | BN1: Clearing status
A2: 1 | B2: Bank buys a forward on the S&P 500 Index at a forward level of $5250. Current S&P 500 level is $5100 | C2: TRD-2026-001 | D2: Equity Index Forward | E2: Long (Buyer) | F2: S&P 500 Index | G2: 28-Aug-2026 | H2: 28-Aug-2027 | I2: Cash-settled | J2: Bank A | K2: - | L2: - | M2: USD | N2: $25,000,000 | O2: - | P2: 25000000 | Q2: USD | R2: 5100 | S2: 5250 | T2: - | U2: - | V2: - | W2: - | X2: - | Y2: - | Z2: - | AA2: - | AB2: - | AC2: - | AD2: - | AE2: - | AF2: S&P 500 Index | AG2: Large-Cap Developed Market Index | AH2: Broad Market / Diversified | AI2: Large Cap | AJ2: - | AK2: - | AL2: - | AM2: - | AP2: - | AQ2: - | AR2: - | AS2: - | AT2: - | AU2: - | AV2: - | AW2: - | AX2: - | AY2: - | AZ2: 5100 | BA2: - | BB2: Equity | BC2: Bucket 11 (Large-Cap, Developed - Indices/Funds) | BD2: Equity Delta - S&P 500 | BE2: Index | BF2: North America (US) | BG2: Index / Diversified | BH2: USD | BI2: - | BJ2: 28-Aug-2027 | BK2: ISDA/CSA - Bilateral VM | BL2: NS-BANKA-EQD | BM2: Bank A | BN2: Uncleared (bilateral OTC)
A3: 2 | B3: Bank buys a 1 year call option on the S&P 500 index. The index is currently at $5000 and the bank pays a premium for the option | C3: TRD-2026-002 | D3: Equity Index Option (Vanilla Call) | E3: Long (Buyer) | F3: S&P 500 Index | G3: 28-Aug-2026 | H3: 28-Aug-2027 | I3: Cash-settled, premium paid upfront | J3: Bank B | K3: - | L3: - | M3: USD | N3: $10,000,000 | O3: - | P3: 10000000 | Q3: USD | R3: 5000 | S3: - | T3: 5200 | U3: - | V3: - | W3: - | X3: - | Y3: - | Z3: - | AA3: - | AB3: - | AC3: - | AD3: - | AE3: - | AF3: S&P 500 Index | AG3: Large-Cap Developed Market Index | AH3: Broad Market / Diversified | AI3: Large Cap | AJ3: - | AK3: - | AL3: - | AM3: - | AP3: - | AQ3: - | AR3: - | AS3: - | AT3: - | AU3: Vanilla Index Option | AV3: Call | AW3: European [assumed] | AX3: 5200 | AY3: 28-Aug-2027 | AZ3: 5000 | BA3: 0.18 | BB3: Equity | BC3: Bucket 11 (Large-Cap, Developed - Indices/Funds) | BD3: Equity Delta & Vega & Curvature - S&P 500 | BE3: Index | BF3: North America (US) | BG3: Index / Diversified | BH3: USD | BI3: 1Y | BJ3: 28-Aug-2027 | BK3: ISDA/CSA - Bilateral VM | BL3: NS-BANKB-EQD | BM3: Bank B | BN3: Uncleared (bilateral OTC)
A4: 3 | B4: Bank buys a 6 month put option on the Euro Stoxx 50 index to protect against a fall in the equity index | C4: TRD-2026-003 | D4: Equity Index Option (Vanilla Put) - Hedge | E4: Long (Buyer) | F4: Euro Stoxx 50 Index | G4: 28-Aug-2026 | H4: 28-Feb-2027 | I4: Cash-settled, premium paid upfront | J4: Bank C | K4: - | L4: - | M4: EUR | N4: EUR 12,000,000 | O4: - | P4: 12000000 | Q4: EUR | R4: 5250 | S4: - | T4: 5000 | U4: - | V4: - | W4: - | X4: - | Y4: - | Z4: - | AA4: - | AB4: - | AC4: - | AD4: - | AE4: - | AF4: Euro Stoxx 50 Index | AG4: Large-Cap Developed Market Index (Europe) | AH4: Broad Market / Diversified | AI4: Large Cap | AJ4: - | AK4: - | AL4: - | AM4: - | AP4: - | AQ4: - | AR4: - | AS4: - | AT4: - | AU4: Vanilla Index Option (Protective/Hedge) | AV4: Put | AW4: European [assumed] | AX4: EUR 5000 | AY4: 28-Feb-2027 | AZ4: EUR 5250 | BA4: 0.2 | BB4: Equity | BC4: Bucket 11 (Large-Cap, Developed - Indices/Funds) | BD4: Equity Delta & Vega & Curvature - Euro Stoxx 50 | BE4: Index | BF4: Europe (Eurozone) | BG4: Index / Diversified | BH4: EUR | BI4: 6M | BJ4: 28-Feb-2027 | BK4: ISDA/CSA - Bilateral VM | BL4: NS-BANKC-EQD | BM4: Bank C | BN4: Uncleared (bilateral OTC)
A5: 4 | B5: Bank receives the total return of the S&P 500 Index and pays a financing rate to the counterparty for the duration of the transaction | C5: TRD-2026-004 | D5: Total Return Swap (Equity) | E5: Receiver of Total Return / Payer of Financing | F5: S&P 500 Index | G5: 28-Aug-2026 | H5: 28-Aug-2029 | I5: Periodic cash settlement + final settlement | J5: Bank D | K5: - | L5: - | M5: USD | N5: $30,000,000 | O5: - | P5: 30000000 | Q5: USD | R5: - | S5: - | T5: - | U5: - | V5: SOFR + 1.20% (financing leg) | W5: - | X5: SOFR | Y5: SOFR OIS | Z5: 3Y | AA5: Quarterly | AB5: Quarterly | AC5: - | AD5: - | AE5: - | AF5: S&P 500 Index | AG5: Large-Cap Developed Market Index | AH5: Broad Market / Diversified | AI5: Large Cap | AJ5: - | AK5: - | AL5: - | AM5: - | AP5: - | AQ5: - | AR5: - | AS5: - | AT5: - | AU5: - | AV5: - | AW5: - | AX5: - | AY5: - | AZ5: 5100 | BA5: - | BB5: Equity | BC5: Equity: Bucket 11 (Index); IR: USD | BD5: Equity Delta - S&P 500; IR Delta - SOFR | BE5: Index / Financing Leg | BF5: North America (US) | BG5: Index / Diversified | BH5: USD | BI5: 3Y | BJ5: 28-Aug-2029 | BK5: ISDA/CSA - Bilateral VM+IM (long-dated swap) | BL5: NS-BANKD-EQD | BM5: Bank D | BN5: Uncleared (bilateral OTC)
A6: 5 | B6: Bank buys a NASDAQ 100 index future. The current index level is $22000 and the agreed futures price is $22150 | C6: TRD-2026-005 | D6: Equity Index Future | E6: Long (Buyer) | F6: NASDAQ 100 Index | G6: 28-Aug-2026 | H6: 18-Dec-2026 | I6: Exchange-cleared, daily variation margin | J6: Bank E | K6: - | L6: - | M6: USD | N6: $20,000,000 | O6: - | P6: 20000000 | Q6: USD | R6: 22000 | S6: 22150 | T6: - | U6: - | V6: - | W6: - | X6: - | Y6: - | Z6: - | AA6: - | AB6: - | AC6: - | AD6: - | AE6: - | AF6: NASDAQ 100 Index | AG6: Large-Cap Developed Market Index (Tech-heavy) | AH6: Technology / Growth | AI6: Large Cap | AJ6: - | AK6: - | AL6: - | AM6: - | AP6: - | AQ6: - | AR6: - | AS6: - | AT6: - | AU6: - | AV6: - | AW6: - | AX6: - | AY6: - | AZ6: 22000 | BA6: - | BB6: Equity | BC6: Bucket 11 (Large-Cap, Developed - Indices/Funds) | BD6: Equity Delta - NASDAQ 100 | BE6: Index | BF6: North America (US) | BG6: Technology / Index | BH6: USD | BI6: - | BJ6: 18-Dec-2026 | BK6: Exchange Initial + Variation Margin (CCP) | BL6: NS-BANKE-ETD | BM6: Bank E | BN6: Centrally cleared (Exchange/CCP)
A7: 6 | B7: Bank buys EUR and sells USD under a 1 year forward contract | C7: TRD-2026-006 | D7: FX Forward | E7: Buy EUR / Sell USD | F7: EUR/USD | G7: 28-Aug-2026 | H7: 28-Aug-2027 | I7: Physical delivery (deliverable forward) | J7: Bank F | K7: EUR | L7: USD | M7: EUR/USD | N7: EUR 15,000,000 | O7: USD 17,625,000 (at forward rate) [derived] | P7: 15000000 | Q7: USD | R7: 1.175 | S7: 1.19 | T7: - | U7: - | V7: - | W7: +150 pips [derived: fwd - spot] | X7: - | Y7: - | Z7: - | AA7: - | AB7: - | AC7: EUR/USD | AD7: G10 (Liquid) | AE7: - | AF7: - | AG7: - | AH7: - | AI7: - | AJ7: - | AK7: - | AL7: - | AM7: - | AP7: - | AQ7: - | AR7: - | AS7: - | AT7: - | AU7: - | AV7: - | AW7: - | AX7: - | AY7: - | AZ7: - | BA7: - | BB7: FX | BC7: FX (single bucket, G10) | BD7: FX Delta - EUR/USD | BE7: G10 Currency Pair | BF7: Global (US/Eurozone) | BG7: - | BH7: USD | BI7: 1Y | BJ7: 28-Aug-2027 | BK7: ISDA/CSA - Bilateral VM | BL7: NS-BANKF-FX | BM7: Bank F | BN7: Uncleared (bilateral OTC)
A8: 7 | B8: Bank buys a EUR/USD call option, giving it the right to buy EUR against USD | C8: TRD-2026-007 | D8: FX Option (Vanilla Call) | E8: Long (Buyer - right to buy EUR) | F8: EUR/USD | G8: 28-Aug-2026 | H8: 28-Feb-2027 | I8: Physical delivery / premium paid upfront | J8: Bank G | K8: EUR | L8: USD | M8: EUR/USD | N8: EUR 10,000,000 | O8: - | P8: 10000000 | Q8: USD | R8: 1.175 | S8: - | T8: 1.18 | U8: - | V8: - | W8: - | X8: - | Y8: - | Z8: - | AA8: - | AB8: - | AC8: EUR/USD | AD8: G10 (Liquid) | AE8: 6M | AF8: - | AG8: - | AH8: - | AI8: - | AJ8: - | AK8: - | AL8: - | AM8: - | AP8: - | AQ8: - | AR8: - | AS8: - | AT8: - | AU8: Vanilla FX Option | AV8: Call (on EUR) | AW8: European [assumed] | AX8: 1.18 | AY8: 28-Feb-2027 | AZ8: 1.175 | BA8: ~7.5% (est., EUR/USD implied vol) [assumed] | BB8: FX | BC8: FX (single bucket, G10) | BD8: FX Delta & Vega - EUR/USD | BE8: G10 Currency Pair | BF8: Global (US/Eurozone) | BG8: - | BH8: USD | BI8: 6M | BJ8: 28-Feb-2027 | BK8: ISDA/CSA - Bilateral VM | BL8: NS-BANKG-FX | BM8: Bank G | BN8: Uncleared (bilateral OTC)
A9: 8 | B9: Bank buys a USD/JPY put option, giving it the right to sell USD against JPY | C9: TRD-2026-008 | D9: FX Option (Vanilla Put) | E9: Long (Buyer - right to sell USD) | F9: USD/JPY | G9: 28-Aug-2026 | H9: 28-Aug-2027 | I9: Physical delivery / premium paid upfront | J9: Bank H | K9: JPY | L9: USD | M9: USD/JPY | N9: - | O9: $8,000,000 | P9: 8000000 | Q9: USD | R9: 148 | S9: - | T9: 145 | U9: - | V9: - | W9: - | X9: - | Y9: - | Z9: - | AA9: - | AB9: - | AC9: USD/JPY | AD9: G10 (Liquid) | AE9: 1Y | AF9: - | AG9: - | AH9: - | AI9: - | AJ9: - | AK9: - | AL9: - | AM9: - | AP9: - | AQ9: - | AR9: - | AS9: - | AT9: - | AU9: Vanilla FX Option | AV9: Put (on USD) | AW9: European [assumed] | AX9: 145 | AY9: 28-Aug-2027 | AZ9: 148 | BA9: ~9.0% (est., USD/JPY implied vol) [assumed] | BB9: FX | BC9: FX (single bucket, G10) | BD9: FX Delta & Vega - USD/JPY | BE9: G10 Currency Pair | BF9: Global (US/Japan) | BG9: - | BH9: USD | BI9: 1Y | BJ9: 28-Aug-2027 | BK9: ISDA/CSA - Bilateral VM | BL9: NS-BANKH-FX | BM9: Bank H | BN9: Uncleared (bilateral OTC)
A10: 9 | B10: Bank enters into a cross-currency swap, paying USD interest and receiving EUR interest over the life of the transaction | C10: TRD-2026-009 | D10: Cross-Currency Swap (USD/EUR) | E10: Pay USD Floating / Receive EUR Floating | F10: USD SOFR vs EUR STR | G10: 28-Aug-2026 | H10: 28-Aug-2031 | I10: Periodic interest exchange + FX notional exchange | J10: Bank I | K10: EUR | L10: USD | M10: USD/EUR | N10: - | O10: $40,000,000 | P10: $40,000,000 | Q10: USD | R10: - | S10: - | T10: - | U10: - | V10: USD: SOFR + 1.00%; EUR: €STR + 0.80% | W10: - | X10: SOFR (USD leg) / €STR (EUR leg) | Y10: SOFR OIS / €STR OIS | Z10: 5Y | AA10: Quarterly | AB10: Quarterly | AC10: EUR/USD | AD10: G10 (Liquid) | AE10: - | AF10: - | AG10: - | AH10: - | AI10: - | AJ10: - | AK10: - | AL10: - | AM10: - | AP10: - | AQ10: - | AR10: - | AS10: - | AT10: - | AU10: - | AV10: - | AW10: - | AX10: - | AY10: - | AZ10: - | BA10: - | BB10: Interest Rate | BC10: USD & EUR (IR); FX (single bucket, G10) | BD10: IR Delta - SOFR & €STR; FX Delta - EUR/USD | BE10: Cross-Currency Basis | BF10: Global (US/Eurozone) | BG10: - | BH10: USD/EUR | BI10: 5Y | BJ10: 28-Aug-2031 | BK10: ISDA/CSA - Bilateral VM+IM (SIMM, long-dated) | BL10: NS-BANKI-XCCY | BM10: Bank I | BN10: Uncleared (bilateral OTC)
A11: 10 | B11: Bank enters into a 6 month EUR/USD FX swap, exchanging EUR and USD initially and reversing the exchange at maturity | C11: TRD-2026-010 | D11: FX Swap (Spot-Forward) | E11: Buy/Sell EUR vs USD near leg, reverse far leg | F11: EUR/USD | G11: 28-Aug-2026 | H11: 28-Feb-2027 | I11: Physical delivery, two legs (near + far) | J11: Bank J | K11: EUR | L11: USD | M11: EUR/USD | N11: EUR 20,000,000 | O11: - | P11: EUR 20,000,000 | Q11: USD | R11: 1.175 | S11: 1.1785 (spot + forward points) [derived] | T11: - | U11: - | V11: - | W11: +35 pips | X11: - | Y11: - | Z11: - | AA11: - | AB11: - | AC11: EUR/USD | AD11: G10 (Liquid) | AE11: - | AF11: - | AG11: - | AH11: - | AI11: - | AJ11: - | AK11: - | AL11: - | AM11: - | AP11: - | AQ11: - | AR11: - | AS11: - | AT11: - | AU11: - | AV11: - | AW11: - | AX11: - | AY11: - | AZ11: - | BA11: - | BB11: FX | BC11: FX (single bucket, G10) | BD11: FX Delta - EUR/USD | BE11: G10 Currency Pair | BF11: Global (US/Eurozone) | BG11: - | BH11: USD | BI11: 6M | BJ11: 28-Feb-2027 | BK11: ISDA/CSA - Bilateral VM | BL11: NS-BANKJ-FX | BM11: Bank J | BN11: Uncleared (bilateral OTC)
A12: 11 | B12: Bank agrees to buy Brent crude oil under a 1 year forward contract at a fixed price | C12: TRD-2026-011 | D12: Commodity Forward (Brent Crude Oil) | E12: Long (Buyer) | F12: Brent Crude Oil | G12: 28-Aug-2026 | H12: 28-Aug-2027 | I12: Cash-settled [assumed] | J12: Bank K | K12: - | L12: - | M12: USD | N12: $12,000,000 | O12: - | P12: $12,000,000 | Q12: USD | R12: $70/barrel | S12: $78/barrel | T12: - | U12: - | V12: - | W12: - | X12: - | Y12: - | Z12: - | AA12: - | AB12: - | AC12: - | AD12: - | AE12: - | AF12: - | AG12: - | AH12: - | AI12: - | AJ12: Energy - Crude Oil (Brent) | AK12: Brent (ICE, North Sea) | AL12: Bucket: Energy - Oil | AM12: 1Y | AN12: Barrels (bbl) | AO12: 153846 | AP12: - | AQ12: - | AR12: - | AS12: - | AT12: - | AU12: - | AV12: - | AW12: - | AX12: - | AY12: - | AZ12: - | BA12: - | BB12: Commodity | BC12: Bucket 6 (Energy - Oil/Gas) | BD12: Commodity Delta - Brent Crude | BE12: Crude Oil | BF12: Global / Europe (Brent benchmark) | BG12: Energy | BH12: USD | BI12: 1Y | BJ12: 28-Aug-2027 | BK12: ISDA/CSA - Bilateral VM | BL12: NS-BANKK-CMD | BM12: Bank K | BN12: Uncleared (bilateral OTC)
A13: 12 | B13: Bank enters into a WTI crude oil futures contract to purchase crude oil at a predetermined futures price | C13: TRD-2026-012 | D13: Commodity Future (WTI Crude Oil) | E13: Long (Buyer) | F13: WTI Crude Oil | G13: 28-Aug-2026 | H13: 20-Nov-2026 | I13: Exchange-cleared, daily variation margin | J13: Bank L | K13: - | L13: - | M13: USD | N13: $12,000,000 | O13: - | P13: $12,000,000 | Q13: USD | R13: $70/barrel | S13: $72/barrel | T13: - | U13: - | V13: - | W13: - | X13: - | Y13: - | Z13: - | AA13: - | AB13: - | AC13: - | AD13: - | AE13: - | AF13: - | AG13: - | AH13: - | AI13: - | AJ13: Energy - Crude Oil (WTI) | AK13: WTI (NYMEX, Cushing OK) | AL13: Bucket: Energy - Oil | AM13: ~3M | AN13: Barrels (bbl) | AO13: 166667 | AP13: - | AQ13: - | AR13: - | AS13: - | AT13: - | AU13: - | AV13: - | AW13: - | AX13: - | AY13: - | AZ13: - | BA13: - | BB13: Commodity | BC13: Bucket 6 (Energy - Oil/Gas) | BD13: Commodity Delta - WTI Crude | BE13: Crude Oil | BF13: North America (US) | BG13: Energy | BH13: USD | BI13: - | BJ13: 20-Nov-2026 | BK13: Exchange Initial + Variation Margin (CCP) | BL13: NS-BANKL-ETD | BM13: Bank L | BN13: Centrally cleared (Exchange/CCP)
A14: 13 | B14: Bank buys a call option on gold, giving it the right to purchase gold at a predetermined price | C14: TRD-2026-013 | D14: Commodity Option (Vanilla Call - Gold) | E14: Long (Buyer) | F14: Gold | G14: 28-Aug-2026 | H14: 28-Feb-2027 | I14: Cash-settled, premium paid upfront [assumed] | J14: Bank M | K14: - | L14: - | M14: USD | N14: $7,000,000 | O14: - | P14: $7,000,000 | Q14: USD | R14: $3,400/oz | S14: - | T14: $3,500/oz | U14: - | V14: - | W14: - | X14: - | Y14: - | Z14: - | AA14: - | AB14: - | AC14: - | AD14: - | AE14: - | AF14: - | AG14: - | AH14: - | AI14: - | AJ14: Precious Metal - Gold | AK14: LBMA / COMEX Good Delivery | AL14: Bucket: Metals - Precious | AM14: 6M | AN14: Troy Ounces (oz) | AO14: 2000 | AP14: - | AQ14: - | AR14: - | AS14: - | AT14: - | AU14: Vanilla Commodity Option | AV14: Call | AW14: European [assumed] | AX14: $3,500/oz | AY14: 28-Feb-2027 | AZ14: $3,400/oz | BA14: ~16% (est., gold implied vol) [assumed] | BB14: Commodity | BC14: Bucket 7 (Metals - Precious) | BD14: Commodity Delta & Vega - Gold | BE14: Precious Metals | BF14: Global | BG14: Metals | BH14: USD | BI14: 6M | BJ14: 28-Feb-2027 | BK14: ISDA/CSA - Bilateral VM | BL14: NS-BANKM-CMD | BM14: Bank M | BN14: Uncleared (bilateral OTC)
A15: 14 | B15: Bank buys a put option on copper, giving it the right to sell copper at a predetermined price | C15: TRD-2026-014 | D15: Commodity Option (Vanilla Put - Copper) | E15: Long (Buyer) | F15: Copper | G15: 28-Aug-2026 | H15: 28-Aug-2027 | I15: Cash-settled, premium paid upfront [assumed] | J15: Bank N | K15: - | L15: - | M15: USD | N15: $6,000,000 | O15: - | P15: $6,000,000 | Q15: USD | R15: $4.74/lb [as per source sheet: $74/lb - likely a typo, flagged] | S15: - | T15: $5.00/lb | U15: - | V15: - | W15: - | X15: - | Y15: - | Z15: - | AA15: - | AB15: - | AC15: - | AD15: - | AE15: - | AF15: - | AG15: - | AH15: - | AI15: - | AJ15: Base Metal - Copper | AK15: LME Grade A Copper | AL15: Bucket: Metals - Base | AM15: 1Y | AN15: Pounds (lb) | AO15: 1200000 | AP15: - | AQ15: - | AR15: - | AS15: - | AT15: - | AU15: Vanilla Commodity Option | AV15: Put | AW15: European [assumed] | AX15: $5.00/lb | AY15: 28-Aug-2027 | AZ15: $4.74/lb [flagged - source shows $74/lb, likely typo] | BA15: ~22% (est., copper implied vol) [assumed] | BB15: Commodity | BC15: Bucket 8 (Metals - Base) | BD15: Commodity Delta & Vega - Copper | BE15: Base Metals | BF15: Global | BG15: Metals | BH15: USD | BI15: 1Y | BJ15: 28-Aug-2027 | BK15: ISDA/CSA - Bilateral VM | BL15: NS-BANKN-CMD | BM15: Bank N | BN15: Uncleared (bilateral OTC)
A16: 15 | B16: Bank enters into an oil commodity swap, paying a fixed oil price and receiving a floating market price for the agreed period | C16: TRD-2026-015 | D16: Commodity Swap (Fixed-for-Floating Oil) | E16: Pay Fixed / Receive Floating | F16: Crude Oil (generic benchmark) | G16: 28-Aug-2026 | H16: 28-Aug-2028 | I16: Periodic cash settlement (net of fixed vs floating) | J16: Bank O | K16: - | L16: - | M16: USD | N16: $18,000,000 | O16: - | P16: $18,000,000 | Q16: USD | R16: $74/barrel | S16: - | T16: - | U16: $76/barrel | V16: Floating market price (avg.) | W16: - | X16: - | Y16: - | Z16: - | AA16: Monthly [assumed] | AB16: Monthly [assumed] | AC16: - | AD16: - | AE16: - | AF16: - | AG16: - | AH16: - | AI16: - | AJ16: Energy - Crude Oil | AK16: Generic / Benchmark | AL16: Bucket: Energy - Oil | AM16: 2Y | AN16: Barrels (bbl) | AO16: 243243 | AP16: - | AQ16: - | AR16: - | AS16: - | AT16: - | AU16: - | AV16: - | AW16: - | AX16: - | AY16: - | AZ16: - | BA16: - | BB16: Commodity | BC16: Bucket 6 (Energy - Oil/Gas) | BD16: Commodity Delta - Oil Swap | BE16: Crude Oil | BF16: Global | BG16: Energy | BH16: USD | BI16: 2Y | BJ16: 28-Aug-2028 | BK16: ISDA/CSA - Bilateral VM | BL16: NS-BANKO-CMD | BM16: Bank O | BN16: Uncleared (bilateral OTC)
A17: 16 | B17: Bank enters into a 5 year interest rate swap, paying a fixed interest rate and receiving 3 month SOFR | C17: TRD-2026-016 | D17: Interest Rate Swap (Fixed vs Floating) | E17: Pay Fixed / Receive Floating | F17: USD SOFR | G17: 28-Aug-2026 | H17: 28-Aug-2031 | I17: Periodic net interest cash settlement | J17: Bank P | K17: - | L17: - | M17: USD | N17: $50,000,000 | O17: - | P17: $50,000,000 | Q17: USD | R17: - | S17: - | T17: - | U17: 0.042 | V17: 3M SOFR | W17: - | X17: SOFR | Y17: SOFR Swap Curve | Z17: 5Y | AA17: Quarterly | AB17: Quarterly | AC17: - | AD17: - | AE17: - | AF17: - | AG17: - | AH17: - | AI17: - | AJ17: - | AK17: - | AL17: - | AM17: - | AP17: - | AQ17: - | AR17: - | AS17: - | AT17: - | AU17: - | AV17: - | AW17: - | AX17: - | AY17: - | AZ17: - | BA17: - | BB17: Interest Rate | BC17: USD | BD17: IR Delta - SOFR Swap Curve | BE17: Vanilla IRS | BF17: North America (US) | BG17: - | BH17: USD | BI17: 5Y | BJ17: 28-Aug-2031 | BK17: ISDA/CSA - Bilateral VM+IM (SIMM) | BL17: NS-BANKP-IRD | BM17: Bank P | BN17: Likely centrally cleared (LCH/CME) - standard USD SOFR IRS [assumed]
A18: 17 | B18: Bank enters into a 3 year SOFR OIS, paying a fixed rate and receiving compounded SOFR overnight interest | C18: TRD-2026-017 | D18: Overnight Index Swap (OIS) | E18: Pay Fixed / Receive Floating (Compounded) | F18: USD SOFR | G18: 28-Aug-2026 | H18: 28-Aug-2029 | I18: Periodic net interest cash settlement | J18: Bank Q | K18: - | L18: - | M18: USD | N18: $35,000,000 | O18: - | P18: $35,000,000 | Q18: USD | R18: - | S18: - | T18: - | U18: 0.0395 | V18: SOFR (compounded overnight) | W18: - | X18: SOFR | Y18: SOFR OIS Curve | Z18: 3Y | AA18: Daily | AB18: Annual | AC18: - | AD18: - | AE18: - | AF18: - | AG18: - | AH18: - | AI18: - | AJ18: - | AK18: - | AL18: - | AM18: - | AP18: - | AQ18: - | AR18: - | AS18: - | AT18: - | AU18: - | AV18: - | AW18: - | AX18: - | AY18: - | AZ18: - | BA18: - | BB18: Interest Rate | BC18: USD | BD18: IR Delta - SOFR OIS Curve | BE18: OIS | BF18: North America (US) | BG18: - | BH18: USD | BI18: 3Y | BJ18: 28-Aug-2029 | BK18: ISDA/CSA - Bilateral VM+IM (SIMM) | BL18: NS-BANKQ-IRD | BM18: Bank Q | BN18: Likely centrally cleared (LCH/CME) - standard USD SOFR OIS [assumed]
A19: 18 | B19: Bank buys a 2Y x 5Y payer swaption, giving it the right to enter into a 5-Year interest rate swap after 2 years and pay fixed interest | C19: TRD-2026-018 | D19: Interest Rate Swaption (Payer, European) | E19: Long (Buyer) | F19: USD SOFR 5Y Swap | G19: 28-Aug-2026 | H19: 48819 | I19: Physical/cash settlement into underlying swap [assumed] | J19: Bank R | K19: - | L19: - | M19: USD | N19: $25,000,000 | O19: - | P19: $25,000,000 | Q19: USD | R19: - | S19: - | T19: 0.0425 | U19: 0.0425 | V19: 3M SOFR (underlying swap) | W19: - | X19: SOFR | Y19: SOFR Swap Curve | Z19: 2Y into 5Y (2Yx5Y) | AA19: Quarterly | AB19: Quarterly | AC19: - | AD19: - | AE19: - | AF19: - | AG19: - | AH19: - | AI19: - | AJ19: - | AK19: - | AL19: - | AM19: - | AP19: - | AQ19: - | AR19: - | AS19: - | AT19: - | AU19: Interest Rate Swaption (Payer) | AV19: Payer (Call on rates) | AW19: European | AX19: 4.25% | AY19: 46993 | AZ19: 0.0405 | BA19: ~85 bps | BB19: Interest Rate | BC19: USD | BD19: IR Delta & Vega - SOFR Swap Curve (Swaption) | BE19: Swaption | BF19: North America (US) | BG19: - | BH19: USD | BI19: 2Yx5Y | BJ19: 28-Aug-2028 | BK19: ISDA/CSA - Bilateral VM+IM (SIMM) | BL19: NS-BANKR-IRD | BM19: Bank R | BN19: Uncleared (bilateral OTC) - swaptions typically not centrally cleared
A20: 19 | B20: Bank buys a 3-Year SOFR cap, providing protection if SOFR rises above the agreed strike rate | C20: TRD-2026-019 | D20: Interest Rate Cap | E20: Long (Buyer) | F20: 3M SOFR | G20: 28-Aug-2026 | H20: 28-Aug-2029 | I20: Periodic cash settlement if SOFR > strike | J20: Bank S | K20: - | L20: - | M20: USD | N20: $20,000,000 | O20: - | P20: $20,000,000 | Q20: USD | R20: - | S20: - | T20: 0.045 | U20: - | V20: 3M SOFR | W20: - | X20: SOFR | Y20: SOFR Cap/Floor Curve | Z20: 3Y | AA20: Quarterly | AB20: Quarterly | AC20: - | AD20: - | AE20: - | AF20: - | AG20: - | AH20: - | AI20: - | AJ20: - | AK20: - | AL20: - | AM20: - | AP20: - | AQ20: - | AR20: - | AS20: - | AT20: - | AU20: Interest Rate Cap (strip of caplets) | AV20: Cap (Call on rates) | AW20: European (per caplet) | AX20: 4.50% | AY20: 28-Aug-2029 | AZ20: 0.038 | BA20: ~80 bps | BB20: Interest Rate | BC20: USD | BD20: IR Delta & Vega - SOFR Curve (Cap) | BE20: Cap/Floor | BF20: North America (US) | BG20: - | BH20: USD | BI20: 3Y | BJ20: 28-Aug-2029 | BK20: ISDA/CSA - Bilateral VM | BL20: NS-BANKS-IRD | BM20: Bank S | BN20: Uncleared (bilateral OTC)
A21: 20 | B21: Bank enters into a 6 x 9 USD FRA, fixing the interest rate for a 3 month borrowing period beginning in 6 months | C21: TRD-2026-020 | D21: Forward Rate Agreement (FRA) | E21: Fix Borrowing Rate (Buyer of FRA) | F21: 3M USD Rate | G21: 28-Aug-2026 | H21: 28-Feb-2027 | I21: Single net cash settlement at start of borrowing period | J21: Bank T | K21: - | L21: - | M21: USD | N21: $15,000,000 | O21: - | P21: $15,000,000 | Q21: USD | R21: - | S21: - | T21: - | U21: 0.041 | V21: 3M reference rate (currently 3.85%) | W21: - | X21: SOFR | Y21: Money Market Curve | Z21: 6x9 (3-month period starting in 6 months) | AA21: Single fixing at start | AB21: Single settlement | AC21: - | AD21: - | AE21: - | AF21: - | AG21: - | AH21: - | AI21: - | AJ21: - | AK21: - | AL21: - | AM21: - | AP21: - | AQ21: - | AR21: - | AS21: - | AT21: - | AU21: - | AV21: - | AW21: - | AX21: - | AY21: - | AZ21: - | BA21: - | BB21: Interest Rate | BC21: USD | BD21: IR Delta - Money Market Curve (FRA) | BE21: FRA | BF21: North America (US) | BG21: - | BH21: USD | BI21: 6M-9M bucket | BJ21: 28-Feb-2027 | BK21: ISDA/CSA - Bilateral VM | BL21: NS-BANKT-IRD | BM21: Bank T | BN21: Uncleared (bilateral OTC) [could also be cleared - assumed uncleared]
A22: 21 | B22: Bank buys credit protection on a single name corporate borrower for 5 years. The bank pays a premium and receives protection if a credit event occurs | C22: TRD-2026-021 | D22: Credit Default Swap (Single-Name) | E22: Protection Buyer | F22: Single-Name Corporate Borrower [name not specified] | G22: 28-Aug-2026 | H22: 28-Aug-2031 | I22: Premium paid periodically; contingent payment on credit event | J22: Bank U | K22: - | L22: - | M22: USD | N22: $10,000,000 | O22: - | P22: $10,000,000 | Q22: USD | R22: - | S22: - | T22: - | U22: 125 bps (CDS spread/premium) | V22: - | W22: - | X22: - | Y22: - | Z22: - | AA22: - | AB22: Quarterly [assumed] | AC22: - | AD22: - | AE22: - | AF22: - | AG22: - | AH22: - | AI22: - | AJ22: - | AK22: - | AL22: - | AM22: - | AP22: Single-Name Corporate Borrower [name not specified in source] | AQ22: BBB (est., typical single-name IG reference) [assumed] | AR22: Corporate - Investment Grade [assumed] | AS22: Senior Unsecured [assumed] | AT22: 5Y | AU22: - | AV22: - | AW22: - | AX22: - | AY22: - | AZ22: - | BA22: - | BB22: Credit | BC22: Bucket 4-7 (Corporate, IG, by sector) [assumed] | BD22: Credit Delta - Single-Name CDS Spread | BE22: Single-Name IG | BF22: Not specified [assumed North America] | BG22: Corporate - Sector not specified | BH22: USD | BI22: 5Y | BJ22: 28-Aug-2031 | BK22: ISDA/CSA - Bilateral VM+IM (SIMM) | BL22: NS-BANKU-CRD | BM22: Bank U | BN22: Uncleared (bilateral OTC) - single-name CDS typically not mandatorily cleared
A23: 22 | B23: Bank buys protection on the CDS investment grade index for 5 years | C23: TRD-2026-022 | D23: Credit Default Swap Index (CDX/iTraxx IG) | E23: Protection Buyer | F23: CDS Investment Grade Index (e.g., CDX.NA.IG / iTraxx Europe) [assumed] | G23: 28-Aug-2026 | H23: 28-Aug-2031 | I23: Premium paid periodically; contingent payment on constituent credit events | J23: Bank V | K23: - | L23: - | M23: USD | N23: $20,000,000 | O23: - | P23: $20,000,000 | Q23: USD | R23: - | S23: - | T23: - | U23: 65 bps (CDS index spread) | V23: - | W23: - | X23: - | Y23: - | Z23: - | AA23: - | AB23: Quarterly [assumed] | AC23: - | AD23: - | AE23: - | AF23: - | AG23: - | AH23: - | AI23: - | AJ23: - | AK23: - | AL23: - | AM23: - | AP23: CDS Investment Grade Index (basket of IG corporates) | AQ23: Investment Grade (index composition) | AR23: Corporate - Investment Grade Index | AS23: Senior Unsecured [assumed] | AT23: 5Y | AU23: - | AV23: - | AW23: - | AX23: - | AY23: - | AZ23: - | BA23: - | BB23: Credit | BC23: Bucket 12 (IG CDS Indices) [assumed] | BD23: Credit Delta - CDS Index Spread | BE23: IG Index | BF23: Not specified [assumed North America/Europe] | BG23: Diversified Corporate | BH23: USD | BI23: 5Y | BJ23: 28-Aug-2031 | BK23: ISDA/CSA - Bilateral VM+IM (SIMM) | BL23: NS-BANKV-CRD | BM23: Bank V | BN23: Likely centrally cleared (ICE Clear Credit) - standard IG CDS index [assumed]
A24: 23 | B24: Bank buys a call option on a CDS index, giving it the right to enter into a CDS index protection at a predetermined spread | C24: TRD-2026-023 | D24: Option on CDS Index (Payer/Call) | E24: Long (Buyer) | F24: CDS Investment Grade Index [assumed] | G24: 28-Aug-2026 | H24: 46446 | I24: Premium paid upfront; exercise into CDS index protection | J24: Bank W | K24: - | L24: - | M24: USD | N24: $12,000,000 | O24: - | P24: $12,000,000 | Q24: USD | R24: - | S24: - | T24: 70 bps (strike spread) | U24: - | V24: - | W24: - | X24: - | Y24: - | Z24: - | AA24: - | AB24: - | AC24: - | AD24: - | AE24: - | AF24: - | AG24: - | AH24: - | AI24: - | AJ24: - | AK24: - | AL24: - | AM24: - | AP24: CDS Investment Grade Index (basket of IG corporates) | AQ24: Investment Grade (index composition) | AR24: Corporate - Investment Grade Index | AS24: Senior Unsecured [assumed] | AT24: 6M (option) into 5Y index [assumed] | AU24: CDS Index Option (Payer/Call on spread) | AV24: Call (right to buy protection) | AW24: European | AX24: 70 bps | AY24: 28-Feb-2027 | AZ24: 65 bps (current index spread) | BA24: ~35% spread vol (est.) [assumed] | BB24: Credit | BC24: Bucket 12 (IG CDS Indices) [assumed] | BD24: Credit Delta & Vega - CDS Index Option | BE24: IG Index Option | BF24: Not specified [assumed North America/Europe] | BG24: Diversified Corporate | BH24: USD | BI24: 6M | BJ24: 28-Feb-2027 | BK24: ISDA/CSA - Bilateral VM+IM (SIMM) | BL24: NS-BANKW-CRD | BM24: Bank W | BN24: Uncleared (bilateral OTC) - CDS index options are not centrally cleared
A25: 24 | B25: Bank enters into a forward contract on a corporate credit spread, agreeing today on a spread level that will apply at a future date | C25: TRD-2026-024 | D25: Forward Contract on Corporate Credit Spread | E25: Long Spread (Buyer of Forward) | F25: Corporate Credit Spread [reference entity not specified] | G25: 28-Aug-2026 | H25: 28-Aug-2027 | I25: Single net cash settlement at maturity based on spread differential | J25: Bank X | K25: - | L25: - | M25: USD | N25: $8,000,000 | O25: - | P25: $8,000,000 | Q25: USD | R25: - | S25: 150 bps (forward spread) | T25: - | U25: - | V25: - | W25: - | X25: - | Y25: - | Z25: - | AA25: - | AB25: - | AC25: - | AD25: - | AE25: - | AF25: - | AG25: - | AH25: - | AI25: - | AJ25: - | AK25: - | AL25: - | AM25: - | AP25: Corporate Credit Spread [name not specified in source] | AQ25: Not specified [assumed BBB/IG] | AR25: Corporate - Investment Grade [assumed] | AS25: Senior Unsecured [assumed] | AT25: 1Y | AU25: - | AV25: - | AW25: - | AX25: - | AY25: - | AZ25: - | BA25: - | BB25: Credit | BC25: Bucket 4-7 (Corporate, IG, by sector) [assumed] | BD25: Credit Delta - Forward Spread | BE25: Single-Name IG | BF25: Not specified [assumed North America] | BG25: Corporate - Sector not specified | BH25: USD | BI25: 1Y | BJ25: 28-Aug-2027 | BK25: ISDA/CSA - Bilateral VM | BL25: NS-BANKX-CRD | BM25: Bank X | BN25: Uncleared (bilateral OTC)

Sheet Market Rates
B2: MARKET RATES | D2: CENTRAL RISK-FREE CURVES & ASSUMPTIONS | W2: Interest Rate Curve Data – Discount & Forward Curves
D3: # Days | E3: 1 | F3: 7 | G3: 30 | H3: 60 | I3: 90 | J3: 180 | K3: 270 | L3: 365 | M3: 548 | N3: 730 | O3: 1095 | P3: 1825 | Q3: 2555 | R3: 3650 | S3: 7300
B4: Currency | C4: Market | D4: Benchmark | E4: ON | F4: 1W | G4: 1M | H4: 2M | I4: 3M | J4: 6M | K4: 9M | L4: 1Y | M4: 18M | N4: 2Y | O4: 3Y | P4: 5Y | Q4: 7Y | R4: 10Y | S4: 20Y | W4: Currency | X4: Index / Curve | Y4: Valuation Date | Z4: Tenor | AA4: Tenor (Years) | AB4: Market Rate | AC4: Day Count | AD4: Compounding | AE4: Discount Factor | AF4: Zero Rate | AG4: Start Tenor (Years) | AH4: Forward Rate
B5: USD | C5: USD | D5: SOFR / U.S. Treasury OIS Curve | E5: 0.037 | F5: 0.0372 | G5: 0.0375 | H5: 0.038 | I5: 0.0385 | J5: 0.04 | K5: 0.0415 | L5: 0.0422 | M5: 0.043 | N5: 0.044 | O5: 0.045 | P5: 0.0455 | Q5: 0.046 | R5: 0.0465 | S5: 0.047 | W5: USD | X5: SOFR | Y5: 2026-08-28 | Z5: ON | AA5: 0.002739726 | AB5: =INDEX($E$5:$S$5,1,MATCH(Z5,$E$4:$S$4,0)) -> 0.037 | AC5: ACT/360 | AD5: Annual | AE5: =1/(1+AB5)^AA5 -> 0.99990047 | AF5: =AB5 -> 0.037 | AG5: 0
B6: EUR | C6: EUR | D6: €STR / EURIBOR Curve | E6: 0.02 | F6: 0.0202 | G6: 0.0205 | H6: 0.0208 | I6: 0.021 | J6: 0.022 | K6: 0.023 | L6: 0.0235 | M6: 0.024 | N6: 0.0245 | O6: 0.025 | P6: 0.0255 | Q6: 0.026 | R6: 0.0265 | S6: 0.027 | W6: USD | X6: SOFR | Y6: 2026-08-28 | Z6: 1W | AA6: 0.019178082 | AB6: =INDEX($E$5:$S$5,1,MATCH(Z6,$E$4:$S$4,0)) -> 0.0372 | AC6: ACT/360 | AD6: Annual | AE6: =1/(1+AB6)^AA6 -> 0.99929977 | AF6: =AB6 -> 0.0372 | AG6: =AA5 -> 0.002739726 | AH6: =(AE5/AE6-1)/(AA6-AA5) -> 0.036567902
B7: GBP | C7: GBP | D7: SONIA / Gilt Curve | E7: 0.042 | F7: 0.0422 | G7: 0.0425 | H7: 0.0428 | I7: 0.043 | J7: 0.044 | K7: 0.045 | L7: 0.0455 | M7: 0.046 | N7: 0.0465 | O7: 0.047 | P7: 0.0475 | Q7: 0.048 | R7: 0.0485 | S7: 0.049 | W7: USD | X7: SOFR | Y7: 2026-08-28 | Z7: 1M | AA7: 0.083333333 | AB7: =INDEX($E$5:$S$5,1,MATCH(Z7,$E$4:$S$4,0)) -> 0.0375 | AC7: ACT/360 | AD7: Annual | AE7: =1/(1+AB7)^AA7 -> 0.99693687 | AF7: =AB7 -> 0.0375 | AG7: =AA6 -> 0.019178082 | AH7: =(AE6/AE7-1)/(AA7-AA6) -> 0.036944137
B8: JPY | C8: JPY | D8: TONA / JGB Curve | E8: 0.004 | F8: 0.0041 | G8: 0.0045 | H8: 0.0048 | I8: 0.005 | J8: 0.006 | K8: 0.008 | L8: 0.009 | M8: 0.01 | N8: 0.011 | O8: 0.013 | P8: 0.014 | Q8: 0.016 | R8: 0.018 | S8: 0.02 | W8: USD | X8: SOFR | Y8: 2026-08-28 | Z8: 2M | AA8: 0.16666667 | AB8: =INDEX($E$5:$S$5,1,MATCH(Z8,$E$4:$S$4,0)) -> 0.038 | AC8: ACT/360 | AD8: Annual | AE8: =1/(1+AB8)^AA8 -> 0.99380332 | AF8: =AB8 -> 0.038 | AG8: =AA7 -> 0.083333333 | AH8: =(AE7/AE8-1)/(AA8-AA7) -> 0.037837123
B9: CHF | C9: CHF | D9: SARON / Swiss Govt Curve | E9: 0.003 | F9: 0.0032 | G9: 0.004 | H9: 0.0045 | I9: 0.005 | J9: 0.007 | K9: 0.01 | L9: 0.0115 | M9: 0.013 | N9: 0.0145 | O9: 0.016 | P9: 0.0175 | Q9: 0.019 | R9: 0.021 | S9: 0.023 | W9: USD | X9: SOFR | Y9: 2026-08-28 | Z9: 3M | AA9: 0.25 | AB9: =INDEX($E$5:$S$5,1,MATCH(Z9,$E$4:$S$4,0)) -> 0.0385 | AC9: ACT/360 | AD9: Annual | AE9: =1/(1+AB9)^AA9 -> 0.99060012 | AF9: =AB9 -> 0.0385 | AG9: =AA8 -> 0.16666667 | AH9: =(AE8/AE9-1)/(AA9-AA8) -> 0.038803125
B10: INR | C10: INR | D10: MIBOR / Indian G-Sec Curve | E10: 0.055 | F10: 0.0552 | G10: 0.056 | H10: 0.057 | I10: 0.058 | J10: 0.06 | K10: 0.062 | L10: 0.063 | M10: 0.064 | N10: 0.065 | O10: 0.066 | P10: 0.067 | Q10: 0.068 | R10: 0.069 | S10: 0.07 | W10: USD | X10: SOFR | Y10: 2026-08-28 | Z10: 6M | AA10: 0.5 | AB10: =INDEX($E$5:$S$5,1,MATCH(Z10,$E$4:$S$4,0)) -> 0.04 | AC10: ACT/360 | AD10: Annual | AE10: =1/(1+AB10)^AA10 -> 0.98058068 | AF10: =AB10 -> 0.04 | AG10: =AA9 -> 0.25 | AH10: =(AE9/AE10-1)/(AA10-AA9) -> 0.04087146
B11: AUD | C11: AUD | D11: AONIA / ACGB Curve | E11: 0.035 | F11: 0.0352 | G11: 0.0355 | H11: 0.0358 | I11: 0.036 | J11: 0.037 | K11: 0.038 | L11: 0.0385 | M11: 0.039 | N11: 0.04 | O11: 0.041 | P11: 0.042 | Q11: 0.043 | R11: 0.044 | S11: 0.045 | W11: USD | X11: SOFR | Y11: 2026-08-28 | Z11: 9M | AA11: 0.75 | AB11: =INDEX($E$5:$S$5,1,MATCH(Z11,$E$4:$S$4,0)) -> 0.0415 | AC11: ACT/360 | AD11: Annual | AE11: =1/(1+AB11)^AA11 -> 0.96996384 | AF11: =AB11 -> 0.0415 | AG11: =AA10 -> 0.5 | AH11: =(AE10/AE11-1)/(AA11-AA10) -> 0.043782397
B12: CAD | C12: CAD | D12: CORRA / GoC Curve | E12: 0.027 | F12: 0.0272 | G12: 0.0275 | H12: 0.0278 | I12: 0.028 | J12: 0.029 | K12: 0.03 | L12: 0.031 | M12: 0.032 | N12: 0.033 | O12: 0.034 | P12: 0.035 | Q12: 0.036 | R12: 0.037 | S12: 0.038 | W12: USD | X12: SOFR | Y12: 2026-08-28 | Z12: 1Y | AA12: 1 | AB12: =INDEX($E$5:$S$5,1,MATCH(Z12,$E$4:$S$4,0)) -> 0.0422 | AC12: ACT/360 | AD12: Annual | AE12: =1/(1+AB12)^AA12 -> 0.95950873 | AF12: =AB12 -> 0.0422 | AG12: =AA11 -> 0.75 | AH12: =(AE11/AE12-1)/(AA12-AA11) -> 0.043585257
B13: SEK | C13: SEK | D13: SWESTR / Swedish Govt Curve | E13: 0.018 | F13: 0.0182 | G13: 0.0185 | H13: 0.019 | I13: 0.0195 | J13: 0.0205 | K13: 0.0215 | L13: 0.022 | M13: 0.0225 | N13: 0.023 | O13: 0.024 | P13: 0.025 | Q13: 0.026 | R13: 0.027 | S13: 0.028 | W13: USD | X13: SOFR | Y13: 2026-08-28 | Z13: 18M | AA13: 1.5 | AB13: =INDEX($E$5:$S$5,1,MATCH(Z13,$E$4:$S$4,0)) -> 0.043 | AC13: ACT/360 | AD13: Annual | AE13: =1/(1+AB13)^AA13 -> 0.93880099 | AF13: =AB13 -> 0.043 | AG13: =AA12 -> 1 | AH13: =(AE12/AE13-1)/(AA13-AA12) -> 0.044115303
B14: NOK | C14: NOK | D14: NOWA / Norwegian Govt Curve | E14: 0.032 | F14: 0.0322 | G14: 0.0325 | H14: 0.033 | I14: 0.0335 | J14: 0.0345 | K14: 0.0355 | L14: 0.036 | M14: 0.0365 | N14: 0.037 | O14: 0.038 | P14: 0.039 | Q14: 0.04 | R14: 0.041 | S14: 0.042 | W14: USD | X14: SOFR | Y14: 2026-08-28 | Z14: 2Y | AA14: 2 | AB14: =INDEX($E$5:$S$5,1,MATCH(Z14,$E$4:$S$4,0)) -> 0.044 | AC14: ACT/360 | AD14: Annual | AE14: =1/(1+AB14)^AA14 -> 0.91748506 | AF14: =AB14 -> 0.044 | AG14: =AA13 -> 1.5 | AH14: =(AE13/AE14-1)/(AA14-AA13) -> 0.046465984
B15: DKK | C15: DKK | D15: DESTR / Danish Govt Curve | E15: 0.019 | F15: 0.0192 | G15: 0.0195 | H15: 0.02 | I15: 0.0205 | J15: 0.0215 | K15: 0.0225 | L15: 0.023 | M15: 0.0235 | N15: 0.024 | O15: 0.025 | P15: 0.026 | Q15: 0.027 | R15: 0.028 | S15: 0.029 | W15: USD | X15: SOFR | Y15: 2026-08-28 | Z15: 3Y | AA15: 3 | AB15: =INDEX($E$5:$S$5,1,MATCH(Z15,$E$4:$S$4,0)) -> 0.045 | AC15: ACT/360 | AD15: Annual | AE15: =1/(1+AB15)^AA15 -> 0.8762966 | AF15: =AB15 -> 0.045 | AG15: =AA14 -> 2 | AH15: =(AE14/AE15-1)/(AA15-AA14) -> 0.047002874
B16: NZD | C16: NZD | D16: NZONIA / NZ Govt Curve | E16: 0.036 | F16: 0.0362 | G16: 0.0365 | H16: 0.037 | I16: 0.0375 | J16: 0.0385 | K16: 0.0395 | L16: 0.04 | M16: 0.0405 | N16: 0.041 | O16: 0.042 | P16: 0.043 | Q16: 0.044 | R16: 0.045 | S16: 0.046 | W16: USD | X16: SOFR | Y16: 2026-08-28 | Z16: 5Y | AA16: 5 | AB16: =INDEX($E$5:$S$5,1,MATCH(Z16,$E$4:$S$4,0)) -> 0.0455 | AC16: ACT/360 | AD16: Annual | AE16: =1/(1+AB16)^AA16 -> 0.80053406 | AF16: =AB16 -> 0.0455 | AG16: =AA15 -> 3 | AH16: =(AE15/AE16-1)/(AA16-AA15) -> 0.047320001
B17: HKD | C17: HKD | D17: HONIA / HK Govt Curve | E17: 0.035 | F17: 0.0352 | G17: 0.0355 | H17: 0.036 | I17: 0.0365 | J17: 0.0375 | K17: 0.0385 | L17: 0.039 | M17: 0.0395 | N17: 0.04 | O17: 0.041 | P17: 0.042 | Q17: 0.043 | R17: 0.044 | S17: 0.045 | W17: USD | X17: SOFR | Y17: 2026-08-28 | Z17: 7Y | AA17: 7 | AB17: =INDEX($E$5:$S$5,1,MATCH(Z17,$E$4:$S$4,0)) -> 0.046 | AC17: ACT/360 | AD17: Annual | AE17: =1/(1+AB17)^AA17 -> 0.72992495 | AF17: =AB17 -> 0.046 | AG17: =AA16 -> 5 | AH17: =(AE16/AE17-1)/(AA17-AA16) -> 0.048367377
... B19: CNY | C19: CNY | D19: DR007 / China Govt Curve | E19: 0.016 | F19: 0.0162 | G19: 0.0165 | H19: 0.017 | I19: 0.0175 | J19: 0.0185 | K19: 0.0195 | L19: 0.02 | M19: 0.0205 | N19: 0.021 | O19: 0.022 | P19: 0.023 | Q19: 0.024 | R19: 0.025 | S19: 0.026 | W19: USD | X19: SOFR | Y19: 2026-08-28 | Z19: 20Y | AA19: 20 | AB19: =INDEX($E$5:$S$5,1,MATCH(Z19,$E$4:$S$4,0)) -> 0.047 | AC19: ACT/360 | AD19: Annual | AE19: =1/(1+AB19)^AA19 -> 0.39908588 | AF19: =AB19 -> 0.047 | AG19: =AA18 -> 10 | AH19: =(AE18/AE19-1)/(AA19-AA18) -> 0.059052796
B20: KRW | C20: KRW | D20: KOFR / Korea Govt Curve | E20: 0.028 | F20: 0.0282 | G20: 0.0285 | H20: 0.029 | I20: 0.0295 | J20: 0.0305 | K20: 0.0315 | L20: 0.032 | M20: 0.0325 | N20: 0.033 | O20: 0.034 | P20: 0.035 | Q20: 0.036 | R20: 0.037 | S20: 0.038
B21: MXN | C21: MXN | D21: TIIE / Mexico Govt Curve | E21: 0.075 | F21: 0.0752 | G21: 0.0755 | H21: 0.076 | I21: 0.0765 | J21: 0.0775 | K21: 0.0785 | L21: 0.079 | M21: 0.0795 | N21: 0.08 | O21: 0.081 | P21: 0.082 | Q21: 0.083 | R21: 0.084 | S21: 0.085
B22: BRL | C22: BRL | D22: DI / Brazil Govt Curve | E22: 0.1 | F22: 0.1002 | G22: 0.1005 | H22: 0.101 | I22: 0.1015 | J22: 0.1025 | K22: 0.1035 | L22: 0.104 | M22: 0.1045 | N22: 0.105 | O22: 0.106 | P22: 0.107 | Q22: 0.108 | R22: 0.109 | S22: 0.11 | W22: Additional Curve Inputs / Trade Linkage
B23: ZAR | C23: ZAR | D23: ZAR OIS / SA Govt Curve | E23: 0.07 | F23: 0.0702 | G23: 0.0705 | H23: 0.071 | I23: 0.0715 | J23: 0.0725 | K23: 0.0735 | L23: 0.074 | M23: 0.0745 | N23: 0.075 | O23: 0.076 | P23: 0.077 | Q23: 0.078 | R23: 0.079 | S23: 0.08 | W23: Discount Curve ID | X23: USD-SOFR-OIS
B24: PLN | C24: PLN | D24: POLONIA / Polish Govt Curve | E24: 0.04 | F24: 0.0402 | G24: 0.0405 | H24: 0.041 | I24: 0.0415 | J24: 0.0425 | K24: 0.0435 | L24: 0.044 | M24: 0.0445 | N24: 0.045 | O24: 0.046 | P24: 0.047 | Q24: 0.048 | R24: 0.049 | S24: 0.05 | W24: Forward Curve ID | X24: USD-SOFR-3M
W25: Projection Index | X25: SOFR
W26: Discounting Index | X26: SOFR OIS
W27: Day Count | X27: ACT/360
W28: Business Day Convention | X28: Following
B29: Credit Reference Entity | C29: Reference Obligation | D29: Credit Rating | E29: Credit Bucket | F29: Credit Sector | G29: Seniority | H29: Recovery Rate | I29: 1Y Spread (bps) | J29: 2Y Spread (bps) | K29: 3Y Spread (bps) | L29: 5Y Spread (bps) | M29: 7Y Spread (bps) | N29: 10Y Spread (bps) | O29: Index Series | P29: Effective Date | Q29: Days Count Convention | R29: Upfront Payment (%) | W29: Payment Frequency | X29: Quarterly
B30: Entity A | C30: Reference CDS / Bond | D30: BBB | F30: Industrials | G30: Senior Unsecured | H30: 0.4 | O30: N/A | Q30: ACT/360 | W30: Curve Purpose | X30: PV + projected floating cash flows + IR sensitivities
B31: Entity B | C31: Reference CDS / Bond | D31: A | F31: Financials | G31: Senior Unsecured | H31: 0.4 | O31: N/A | Q31: ACT/360
B32: Entity C | C32: Reference CDS / Bond | D32: BB | F32: Energy | G32: Senior Unsecured | H32: 0.4 | O32: N/A | Q32: ACT/360
B33: CDX.NA.IG | C33: CDS Index | D33: IG | F33: Corporate IG | G33: Senior | H33: 0.4 | O33: CDX.NA.IG | Q33: ACT/360
B34: iTraxx Europe | C34: CDS Index | D34: IG | F34: Corporate IG | G34: Senior | H34: 0.4 | O34: iTraxx Europe | Q34: ACT/360
B37: Purpose | C37: Credit market-rate master table for use by the SIMM trade/calculation sheet.
B38: Input convention | C38: Yellow cells are intended for market data. Populate actual entity/index spreads by tenor; do not use these illustrative entity names as real market observations.
B39: SIMM use | C39: The market spread/curve supports valuation and sensitivity generation. The SIMM calculation then uses the resulting Credit Delta/Vega/Curvature sensitivities as applicable.

Sheet BS Delta
B4: Scenario | C4: Spot | D4: Black-Scholes Option Price | H4: Scenario | I4: Spot | J4: Black-Scholes Option Price
B5: Base | C5: =C14 -> 5000 | D5: 172.67109 | H5: Base | I5: =D14 -> 5250 | J5: 172.67109
B6: Up +15% | C6: =C5*(1+1.5%) -> 5075 | D6: 29.777016 | H6: Up +15% | I6: =I5*(1+1.5%) -> 5328.75 | J6: 29.777016
B7: Down -15% | C7: =C5*(1-15%) -> 4250 | D7: 605.34414 | H7: Down -15% | I7: =I5*(1-15%) -> 4462.5 | J7: 605.34414
B10: Black Scholes Delta Calculations | H10: Vega Calculation | M10: Curvature Calculation | R10: Interest Rate Delta
B12: Header | C12: Trade 1 | D12: Trade 2 | H12: Header | I12: =C12 -> Trade 1 | J12: =D12 -> Trade 2 | M12: Header | N12: =I12 -> Trade 1 | O12: =J12 -> Trade 2 | R12: Header | S12: =N12 -> Trade 1 | V12: Period | W12: Start Date | X12: End Date | Y12: Days | Z12: Year Fraction | AA12: T | AB12: Forward SOFR | AC12: Spread | AD12: Total rate | AE12: cash flow | AF12: Discount Factor | AG12: PV
B13: Trade ID | C13: ='Equity Class Product'!B5 -> TRD-2026-002 | D13: ='Equity Class Product'!B6 -> TRD-2026-003 | H13: Trade ID | I13: =C13 -> TRD-2026-002 | J13: =D13 -> TRD-2026-003 | M13: Trade ID | N13: =I13 -> TRD-2026-002 | O13: =J13 -> TRD-2026-003 | R13: Trade ID | S13: ='Equity Class Product'!B7 -> TRD-2026-004 | V13: 1 | W13: =S18 -> 28-Aug-2026 | X13: =EDATE(W13,3) -> 46354 | Y13: =_xlfn.DAYS(X13,W13) -> 92 | Z13: =Y13/360 -> 0.25555556 | AA13: =(1/S33-1)/S34 -> 0.2464696 | AB13: ='BS Delta'!S35 -> 0.038803125 | AC13: =S24 -> 0.012 | AD13: =AB13+AC13 -> 0.050803125 | AE13: =S17*AD13*Z13 -> 389490.63 | AF13: =S33 -> 0.99060012 | AG13: =AE13*AF13 -> 385829.46
B14: Spot | C14: ='Equity Class Product'!J5 -> 5000 | D14: 5250 | H14: Spot | I14: =C14 -> 5000 | J14: =D14 -> 5250 | M14: Spot | N14: =I14 -> 5000 | O14: =J14 -> 5250 | R14: Product Tyoe | S14: ='Equity Class Product'!C7 -> Total Return Swap (Equity)
B15: Strike | C15: ='Equity Class Product'!L5 -> 5200 | D15: ='Equity Class Product'!L6 -> 5000 | H15: Strike | I15: =C15 -> 5200 | J15: =D15 -> 5000 | M15: Strike | N15: =I15 -> 5200 | O15: =J15 -> 5000 | R15: Position | S15: ='Equity Class Product'!D7 -> Receiver of Total Return / Payer of Financing
B16: Risk free rate | C16: ='Equity Class Product'!AB5 -> 0.0415 | D16: ='Equity Class Product'!AB6 -> 0.021 | H16: Risk free rate | I16: =C16 -> 0.0415 | J16: =D16 -> 0.021 | M16: Risk free rate | N16: =I16 -> 0.0415 | O16: =J16 -> 0.021 | R16: Currency | S16: ='Equity Class Product'!H7 -> USD | V16: Base PV | W16: =AG13 -> 385829.46
B17: Dividend | C17: ='Equity Class Product'!AC5 -> 0.02 | D17: ='Equity Class Product'!AC5 -> 0.02 | H17: Dividend | I17: =C17 -> 0.02 | J17: =D17 -> 0.02 | M17: Dividend | N17: =I17 -> 0.02 | O17: =J17 -> 0.02 | R17: Notional | S17: ='Equity Class Product'!I7 -> 30000000 | V17: PV +1 bp | W17: =S40*S37 -> 386579.48
B18: Volatility | C18: ='Equity Class Product'!U5 -> 0.18 | D18: ='Equity Class Product'!U6 -> 0.2 | H18: Volatility | I18: =C18 -> 0.18 | J18: =D18 -> 0.2 | M18: Volatility | N18: =I18 -> 0.18 | O18: =J18 -> 0.2 | R18: Trade Date | S18: ='Equity Class Product'!F7 -> 28-Aug-2026 | V18: PV -1 bp | W18: =S41*S38 -> 385079.4
B19: Time to Expiry | C19: ='Equity Class Product'!AD5 -> 347 | D19: ='Equity Class Product'!AD6 -> 166 | H19: Time to Expiry | I19: =C19 -> 347 | J19: =D19 -> 166 | M19: Time to Expiry | N19: =I19/365 -> 0.95068493 | O19: =J19/365 -> 0.45479452 | R19: Maturity Date | S19: ='Equity Class Product'!G7 -> 28-Aug-2029 | V19: IR Delta/PV01 | W19: =(W17-W18)/2 -> 750.03995
B20: d1 | C20: =(LN(C14/C15)+(C16-C17+(C18^2)/2)*(C19/365))/(C18*(C19/365)^0.5) -> -0.019258032 | D20: =(LN(D14/D15)+(D16-D17+(D18^2)/2)*(D19/365))/(D18*(D19/365)^0.5) -> 0.43254883 | H20: d1 | I20: =C20 -> -0.019258032 | J20: =D20 -> 0.43254883 | M20: d1 | N20: =C20 -> -0.019258032 | O20: =D20 -> 0.43254883 | R20: Days to Expiry | S20: ='Equity Class Product'!AD7 -> 1078
B21: N(d1) | C21: =_xlfn.NORM.S.DIST(C20,TRUE) -> 0.49231763 | D21: =_xlfn.NORM.S.DIST(D20,TRUE) -> 0.66732871 | H21: N(d1) / PDF(d1) | I21: =_xlfn.NORM.S.DIST(I20,FALSE) -> 0.39886831 | J21: =_xlfn.NORM.S.DIST(J20,FALSE) -> 0.36331401 | M21: N(d1) / PDF(d1) | N21: =_xlfn.NORM.S.DIST(N20,FALSE) -> 0.39886831 | O21: =_xlfn.NORM.S.DIST(O20,FALSE) -> 0.36331401 | R21: Tenor | S21: ='Equity Class Product'!R7 -> 3Y
B22: d2 | C22: =C20-C18*(C19/365)^0.5 -> -0.19476356 | D22: =D20-D18*(D19/365)^0.5 -> 0.29767192 | H22: Call/put | I22: =C24 -> Call | J22: =D24 -> Put | M22: Call/put | N22: =I22 -> Call | O22: =J22 -> Put | R22: Floating Index | S22: ='Equity Class Product'!O7 -> SOFR + 1.20% (financing leg)
B23: N(d2) | C23: =_xlfn.NORM.S.DIST(C22,TRUE) -> 0.42278902 | D23: =_xlfn.NORM.S.DIST(D22,TRUE) -> 0.61702321 | H23: Vega | I23: =I14*EXP(-I17*(I19/365))*I21*(I19/365)^0.5 -> 1907.9206 | J23: =J14*EXP(-J17*(J19/365))*J21*(J19/365)^0.5 -> 1274.6729 | M23: Gamma | N23: =EXP(-N17*N19)*N21/(N14*N18*N19^0.5) -> 0.00044597568 | O23: =EXP(-O17*O19)*O21/(O14*O18*O19^0.5) -> 0.00050843442 | R23: Sub Curve | S23: ='Equity Class Product'!Q7 -> SOFR OIS
B24: Call/put | C24: Call | D24: Put | H24: Vega for 1% | I24: =I23/100 -> 19.079206 | J24: =J23/100 -> 12.746729 | M24: SIMM Shock | N24: 0.15 | O24: 0.15 | R24: Spread | S24: 0.012
B25: Delta | C25: =IF(C24="Call",EXP(-C17*(C19/365))*C21,EXP(-C17*(C19/365))*(C21-1)) -> 0.48304528 | D25: =IF(D24="call",EXP(-D17*(D19/365))*D21,EXP(-D17*(D19/365))*(D21-1)) -> -0.32965907 | M25: Up Shock Spot | N25: =N$14*(1+N$24) -> 5750 | O25: =O$14*(1+O$24) -> 6037.5 | R25: Reset Frequency | S25: ='Equity Class Product'!S7 -> Quarterly
B26: Delta Amount | C26: =C14*C25 -> 2415.2264 | D26: =D14*D25 -> -1730.7101 | M26: Down Shock Spot | N26: =N$14*(1-N$24) -> 4250 | O26: =O$14*(1-O$24) -> 4462.5 | R26: Payment Frequency | S26: ='Equity Class Product'!T7 -> Quarterly
M27: Base Option Value | N27: =C28 -> 301.77318 | O27: =D28 -> 165.97246 | R27: Day Count | S27: ACT/360
B28: Option Price | C28: =IF(C24="call",C14*EXP(-C17*(C19/365))*C21-C15*EXP(-C16*(C19/365))*C23,C15*EXP(-C16*(C19/365))*(1-C23)-C14*EXP(-C17*(C19/365))*(1-C21)) -> 301.77318 | D28: =IF(D24="call",D14*EXP(-D17*(D19/365))*D21-D15*EXP(-D16*(D19/365))*D23,D15*EXP(-D16*(D19/365))*(1-D23)-D14*EXP(-D17*(D19/365))*(1-D21)) -> 165.97246 | M28: Up Shock Option Value | N28: 787.564 | O28: 31.5877 | R28: Discount Curve | S28: USD-SOFR-OIS
M29: Down Shock Option Value | N29: 67.4035 | O29: 606.6288 | R29: Projection Curve | S29: USD-SOFR-3M
B31: Option Prices | C31: =C28 -> 301.77318 | D31: =D28 -> 165.97246 | M31: Up P&L | N31: =N28-N27 -> 485.79082 | O31: =O28-O27 -> -134.38476
B32: Delta | C32: =C25 -> 0.48304528 | D32: =D25 -> -0.32965907 | F32: Step 1 | G32: Calculate the expiry Scaling factor after Up and down curvature residual | M32: Down P&L | N32: =N29-N27 -> -234.36968 | O32: =O29-O27 -> 440.65634 | R32: Market Rate | S32: ='Market Rates'!AB9 -> 0.0385
B33: Vega | C33: =I23 -> 1907.9206 | D33: =J23 -> 1274.6729 | G33: Trade 1 | H33: Trade 2 | R33: Discount Factor | S33: ='Market Rates'!AE9 -> 0.99060012
B34: Gamma | C34: =N23 -> 0.00044597568 | D34: =O23 -> 0.00050843442 | F34: SF | G34: =0.5*(MIN(1,14/C19)) -> 0.020172911 | H34: =0.5*(MIN(1,14/D19)) -> 0.042168675 | M34: Up Delta P&L | N34: =C25*(N25-C14) -> 362.28396 | O34: =D25*(O25-D14) -> -259.60651 | R34: Zero rate | S34: ='Market Rates'!AF9 -> 0.0385
M35: Down Delta P&L | N35: =C25*(N26-C14) -> -362.28396 | O35: =D25*(O26-D14) -> 259.60651 | R35: Forward SOFR | S35: ='Market Rates'!AH9 -> 0.038803125
R36: Notional | S36: =S17 -> 30000000
M37: Up Curvature Residual | N37: =N31-N34 -> 123.50686 | O37: =O31-O34 -> 125.22175 | R37: Discount Factor +1 | S37: =1/(1+(S34+0.01%)*AA13) -> 0.99057593
M38: Down Curvature Residual | N38: =N32-N35 -> 127.91429 | O38: =O32-O35 -> 181.04983 | R38: Discount Factor -1 | S38: =1/(1+(S34-0.01%)*AA13) -> 0.9906243
M40: Scaling factor | N40: =G34 -> 0.020172911 | O40: =H34 -> 0.042168675 | R40: Cash Flow up | S40: =S36*Z13*(AD13+0.01%) -> 390257.29
R41: Cash Flow Down | S41: =S36*Z13*(AD13-0.01%) -> 388723.96
M42: CVR - Long | N42: =C33*C18*N40 -> 6.9278961 | O42: =D33*D18*O40 -> 10.750254
M43: CVR - Short | N43: =-N42 -> -6.9278961 | O43: =-O42 -> -10.750254

Sheet Interest Rate Product
B3: Trade Identification | C3: Product Type | D3: Position | E3: Underlying/Reference | F3: Trade Date | G3: Maturity/Expiry | H3: Currency | I3: Trade Notional | J3: Fixed Rate | K3: Floating rate / Index | L3: Payment Frequency | M3: Reset Frequency | N3: Sensitivity Currency | O3: SIMM Risk Factor | P3: SIMM Bucket | Q3: Day Count Convention | R3: Discount Curve | S3: Forward Curve | T3: Time to Maturity | U3: IR Delta Method | V3: Delta Direction Sign | W3: Delta Value | X3: Interest Rate Delta Sensitivity | Y3: Notes
B4: {=_xlfn._xlws.FILTER(_xlfn.XLOOKUP(B$3,'Trades Inputs'!$C$1:$BN$1,'Trades Inputs'!$C2:$BN25),ISNUMBER(SEARCH("Interest",'Trades Inputs'!$BB2:$BB25)))} -> TRD-2026-009 | C4: {=_xlfn._xlws.FILTER(_xlfn.XLOOKUP(C$3,'Trades Inputs'!$C$1:$BN$1,'Trades Inputs'!$C2:$BN25),ISNUMBER(SEARCH("Interest",'Trades Inputs'!$BB2:$BB25)))} -> Cross-Currency Swap (USD/EUR) | D4: {=_xlfn._xlws.FILTER(_xlfn.XLOOKUP(D$3,'Trades Inputs'!$C$1:$BN$1,'Trades Inputs'!$C2:$BN25),ISNUMBER(SEARCH("Interest",'Trades Inputs'!$BB2:$BB25)))} -> Pay USD Floating / Receive EUR Floating | E4: {=_xlfn._xlws.FILTER(_xlfn.XLOOKUP(E$3,'Trades Inputs'!$C$1:$BN$1,'Trades Inputs'!$C2:$BN25),ISNUMBER(SEARCH("Interest",'Trades Inputs'!$BB2:$BB25)))} -> USD SOFR vs EUR STR | F4: {=_xlfn._xlws.FILTER(_xlfn.XLOOKUP(F$3,'Trades Inputs'!$C$1:$BN$1,'Trades Inputs'!$C2:$BN25),ISNUMBER(SEARCH("Interest",'Trades Inputs'!$BB2:$BB25)))} -> 28-Aug-2026 | G4: {=_xlfn._xlws.FILTER(_xlfn.XLOOKUP(G$3,'Trades Inputs'!$C$1:$BN$1,'Trades Inputs'!$C2:$BN25),ISNUMBER(SEARCH("Interest",'Trades Inputs'!$BB2:$BB25)))} -> 28-Aug-2031 | H4: {=_xlfn._xlws.FILTER(_xlfn.XLOOKUP(H$3,'Trades Inputs'!$C$1:$BN$1,'Trades Inputs'!$C2:$BN25),ISNUMBER(SEARCH("Interest",'Trades Inputs'!$BB2:$BB25)))} -> USD/EUR | I4: {=_xlfn._xlws.FILTER(_xlfn.XLOOKUP(I$3,'Trades Inputs'!$C$1:$BN$1,'Trades Inputs'!$C2:$BN25),ISNUMBER(SEARCH("Interest",'Trades Inputs'!$BB2:$BB25)))} -> $40,000,000 | ... P4: {=_xlfn._xlws.FILTER(_xlfn.XLOOKUP(P$3,'Trades Inputs'!$C$1:$BN$1,'Trades Inputs'!$C2:$BN25),ISNUMBER(SEARCH("Interest",'Trades Inputs'!$BB2:$BB25)))} -> USD & EUR (IR); FX (single bucket, G10) | Q4: ACT/360 | R4: USD SOFR OIS / EUR €STR OIS | S4: USD SOFR / EUR €STR | T4: =G4-TODAY() -> 1808 | U4: {=_xlfn._xlws.FILTER(_xlfn.XLOOKUP(U$3,'Trades Inputs'!$C$1:$BN$1,'Trades Inputs'!$C2:$BN25),ISNUMBER(SEARCH("Interest",'Trades Inputs'!$BB2:$BB25)))} -> #N/A | V4: {=_xlfn._xlws.FILTER(_xlfn.XLOOKUP(V$3,'Trades Inputs'!$C$1:$BN$1,'Trades Inputs'!$C2:$BN25),ISNUMBER(SEARCH("Interest",'Trades Inputs'!$BB2:$BB25)))} -> #N/A | W4: {=_xlfn._xlws.FILTER(_xlfn.XLOOKUP(W$3,'Trades Inputs'!$C$1:$BN$1,'Trades Inputs'!$C2:$BN25),ISNUMBER(SEARCH("Interest",'Trades Inputs'!$BB2:$BB25)))} -> #N/A | X4: {=_xlfn._xlws.FILTER(_xlfn.XLOOKUP(X$3,'Trades Inputs'!$C$1:$BN$1,'Trades Inputs'!$C2:$BN25),ISNUMBER(SEARCH("Interest",'Trades Inputs'!$BB2:$BB25)))} -> #N/A | Y4: {=_xlfn._xlws.FILTER(_xlfn.XLOOKUP(Y$3,'Trades Inputs'!$C$1:$BN$1,'Trades Inputs'!$C2:$BN25),ISNUMBER(SEARCH("Interest",'Trades Inputs'!$BB2:$BB25)))} -> #N/A
B5: TRD-2026-016 | C5: Interest Rate Swap (Fixed vs Floating) | D5: Pay Fixed / Receive Floating | E5: USD SOFR | F5: 28-Aug-2026 | G5: 28-Aug-2031 | H5: USD | I5: $50,000,000 | J5: 0.042 | K5: 3M SOFR | L5: Quarterly | M5: Quarterly | N5: USD | O5: IR Delta - SOFR Swap Curve | P5: USD | Q5: ACT/360 | R5: USD SOFR OIS | S5: USD SOFR 3M | T5: =G5-TODAY() -> 1808
B6: TRD-2026-017 | C6: Overnight Index Swap (OIS) | D6: Pay Fixed / Receive Floating (Compounded) | E6: USD SOFR | F6: 28-Aug-2026 | G6: 28-Aug-2029 | H6: USD | I6: $35,000,000 | J6: 0.0395 | K6: SOFR (compounded overnight) | L6: Annual | M6: Daily | N6: USD | O6: IR Delta - SOFR OIS Curve | P6: USD | Q6: ACT/360 | R6: USD SOFR OIS | S6: USD SOFR OIS | T6: =G6-TODAY() -> 1078
B7: TRD-2026-018 | C7: Interest Rate Swaption (Payer, European) | D7: Long (Buyer) | E7: USD SOFR 5Y Swap | F7: 28-Aug-2026 | G7: 48819 | H7: USD | I7: $25,000,000 | J7: 0.0425 | K7: 3M SOFR (underlying swap) | L7: Quarterly | M7: Quarterly | N7: USD | O7: IR Delta & Vega - SOFR Swap Curve (Swaption) | P7: USD | Q7: ACT/360 | R7: USD SOFR OIS | S7: USD SOFR 3M Swap Curve | T7: =G7-TODAY() -> 2539
B8: TRD-2026-019 | C8: Interest Rate Cap | D8: Long (Buyer) | E8: 3M SOFR | F8: 28-Aug-2026 | G8: 28-Aug-2029 | H8: USD | I8: $20,000,000 | J8: - | K8: 3M SOFR | L8: Quarterly | M8: Quarterly | N8: USD | O8: IR Delta & Vega - SOFR Curve (Cap) | P8: USD | Q8: ACT/360 | R8: USD SOFR OIS | S8: USD SOFR 3M | T8: =G8-TODAY() -> 1078
B9: TRD-2026-020 | C9: Forward Rate Agreement (FRA) | D9: Fix Borrowing Rate (Buyer of FRA) | E9: 3M USD Rate | F9: 28-Aug-2026 | G9: 28-Feb-2027 | H9: USD | I9: $15,000,000 | J9: 0.041 | K9: 3M reference rate (currently 3.85%) | L9: Single settlement | M9: Single fixing at start | N9: USD | O9: IR Delta - Money Market Curve (FRA) | P9: USD | Q9: ACT/360 | R9: USD SOFR OIS | S9: USD SOFR 3M / Money Market Curve | T9: =G9-TODAY() -> #VALUE!

Sheet IR Cash Flow
A1: Interest Rate Products – Cash Flow & Present Value
A2: Valuation date | B2: 46262 | D2: Method | E2: Trade-date cash-flow schedule; PV discounted from each payment date using the USD SOFR/OIS curve
A4: Inputs / Assumptions | E4: USD SOFR/OIS Curve (from Market Rates)
A5: Cap strike (TRD-2026-019) | B5: 0.045 | C5: Enter strike rate; required to calculate cap cash flows/PV | E5: Tenor | F5: Days | G5: Zero Rate
