Workbook

Sheet Sheet1
C3: Debt Waterfall
C5: Smile Brands LLC is a Fictional company that operates a hydropower plant in a fictional country of UK. The hydropower plant has just been constructed and the plant is just about to start operations on October 1, 2021
C7: The project is being operated under a Public-Private Partnership structure. It is supposed to be handed back to government after 20 years of operations on September 30, 2041. This is expected to be a large enough time span for the project to be interesting for private investors.
C9: Financial Model
C10: You have been hired by Smile to help them forecast their debt and equity waterfall. Your goal is to create a 20-year quarterly financial model, focusing on debt repayment and equity distributions.
C12: Assumptions Project Revenues
C13: · Its is expected that if Smile was operating the full year 2021, its operations would generate earnings before debt service of $40m in the year 2021 (cash revenues from electricity sales less operational cash expenses).
C14: i) This amount is called CFADS (cash flow available for debt service).
C15: ii) Every year Smile’s annual CFADS are expected to increase by 2% vs. last year’s annual CFADS. This increase will happen starting from the year 2022, i.e. in the 2nd quarter of operations.
C16: · Assume no further CAPEX and no taxes for the project (it is tax-exempt as the government desperately need the massive environment-friendly power plant).
C17: i) As a result, you may assume that CFADS is also equal to EBITDA which will be later used in debt covenants calculations.
C18: · It is expected that project revenues will vary from quarter to quarter as different amounts of energy will be produced. As a result, the project will generate 25% of its annual CFADS in the 1st quarter of the year, 35% of annual CFADS in the 2nd quarter of the year and 20% of annual CFADS in the remaining quarters.
... C64: Calculate IRR, total interest and accelerated debt payments.

Sheet Assumptions
F2: Smile Brands LLC
F3: Debt Waterfall
F4: Inputs and Assumptions
A7: # | B7: 1. General Assumptions
B9: General | F9: Equity Investment
B10: Company name | C10: (Name) | D10: Smile Brands LLC | F10: Equity Investment Amount | G10: ($) | H10: 80000000
B11: Model start Date | C11: (Date) | D11: 44470 | F11: Transaction Date | G11: (Date) | H11: 43738
F12: Dividend Rate | G12: (%) | H12: 0.6
F13: Discount Rate | G13: (%) | H13: 0.12
A15: # | B15: 2. Model Assumptions
B17: Operational Cashflow
B18: Annual CFADS, 2021 | C18: ($) | D18: 40000000
B19: CFADS Annual Growth Rate | C19: (%) | D19: 0.02
B22: CFADS Seasonality
B23: Q1 | C23: (%) | D23: 0.25
B24: Q2 | C24: (%) | D24: 0.35
B25: Q3 | C25: (%) | D25: 0.2
B26: Q4 | C26: (%) | D26: 0.2
A29: # | B29: 3. Debt Assumptions
B31: Senior Debt | F31: SOFR Forecast
B32: Opening Balance | C32: ($) | D32: 250000000 | F32: Date from | H32: Rate | I32: Quarters to next Inc per Q
B33: Target DSCR | C33: (x) | D33: 1.75 | F33: 44470 | G33: (%) | H33: 0.005 | I33: =YEARFRAC(F34,F33)*4 -> 1 | J33: =(H34-H33)/I33 -> 0.0017
B34: Spread to SOFR | C34: (%) | D34: 0.025 | F34: =EDATE(F33,3) -> 44562 | G34: (%) | H34: 0.0067 | I34: =YEARFRAC(F35,F34)*4 -> 4 | J34: =(H35-H34)/I34 -> 0.000825
B35: Max Term | C35: (Years) | D35: 15 | F35: =EDATE(F34,12) -> 44927 | G35: (%) | H35: 0.01 | I35: =YEARFRAC(F36,F35)*4 -> 4 | J35: =(H36-H35)/I35 -> 0.0025
F36: =EDATE(F35,12) -> 45292 | G36: (%) | H36: 0.02 | I36: =YEARFRAC(F37,F36)*4 -> 4 | J36: =(H37-H36)/I36 -> 0.0025
F37: =EDATE(F36,12) -> 45658 | G37: (%) | H37: 0.03 | I37: =YEARFRAC(F38,F37)*4 -> 4 | J37: =(H38-H37)/I37 -> 0.00125
B38: Subordinate Debt | F38: =EDATE(F37,12) -> 46023 | G38: (%) | H38: 0.035
B39: Opening Balance | C39: ($) | D39: 70000000
B40: Interest Rate -1st Year | C40: (%) | D40: 0.065
B41: Max Term | C41: (Years) | D41: 17.5 | F41: Subordinate Debt Interest Rate
F42: Debt/EBITDA
B43: Revolving Line of Credit | F43: 0 | G43: (%) | H43: 0.05
B44: Opening Balance | C44: ($) | D44: 0 | F44: 1.5 | G44: (%) | H44: 0.055
B45: Max Limit | C45: ($) | D45: 5000000 | F45: 2 | G45: (%) | H45: 0.06
B46: Spread to SOFR | C46: (%) | D46: 0.07 | F46: 3 | G46: (%) | H46: 0.065
F47: 4 | G47: (%) | H47: 0.125

Sheet Model
A1: Q Start | C1: =Assumptions!D11 -> 44470 | D1: =C2+1 -> 44562 | E1: =D2+1 -> 44652 | F1: =E2+1 -> 44743 | G1: =F2+1 -> 44835 | H1: =G2+1 -> 44927 | I1: =H2+1 -> 45017 | J1: =I2+1 -> 45108 | K1: =J2+1 -> 45200 | ... CD1: =CC2+1 -> 51683
A2: Q End | B2: =Assumptions!H11 -> 43738 | C2: =EOMONTH(C1,2) -> 44561 | D2: =EOMONTH(D1,2) -> 44651 | E2: =EOMONTH(E1,2) -> 44742 | F2: =EOMONTH(F1,2) -> 44834 | G2: =EOMONTH(G1,2) -> 44926 | H2: =EOMONTH(H1,2) -> 45016 | I2: =EOMONTH(I1,2) -> 45107 | J2: =EOMONTH(J1,2) -> 45199 | ... CD2: =EOMONTH(CD1,2) -> 51774
A4: CFADS index | C4: 1 | D4: =C4*(1+IF(MONTH(D1)=1,Assumptions!$D$19,0)) -> 1.02 | E4: =D4*(1+IF(MONTH(E1)=1,Assumptions!$D$19,0)) -> 1.02 | F4: =E4*(1+IF(MONTH(F1)=1,Assumptions!$D$19,0)) -> 1.02 | G4: =F4*(1+IF(MONTH(G1)=1,Assumptions!$D$19,0)) -> 1.02 | H4: =G4*(1+IF(MONTH(H1)=1,Assumptions!$D$19,0)) -> 1.0404 | I4: =H4*(1+IF(MONTH(I1)=1,Assumptions!$D$19,0)) -> 1.0404 | J4: =I4*(1+IF(MONTH(J1)=1,Assumptions!$D$19,0)) -> 1.0404 | K4: =J4*(1+IF(MONTH(K1)=1,Assumptions!$D$19,0)) -> 1.0404 | ... CD4: =CC4*(1+IF(MONTH(CD1)=1,Assumptions!$D$19,0)) -> 1.4859474
A5: Seasonality | C5: {=INDEX(Assumptions!$D$23:$D$26,MONTH(C$2)/3)} -> 0.2 | D5: {=INDEX(Assumptions!$D$23:$D$26,MONTH(D$2)/3)} -> 0.25 | E5: {=INDEX(Assumptions!$D$23:$D$26,MONTH(E$2)/3)} -> 0.35 | F5: {=INDEX(Assumptions!$D$23:$D$26,MONTH(F$2)/3)} -> 0.2 | G5: {=INDEX(Assumptions!$D$23:$D$26,MONTH(G$2)/3)} -> 0.2 | H5: {=INDEX(Assumptions!$D$23:$D$26,MONTH(H$2)/3)} -> 0.25 | I5: {=INDEX(Assumptions!$D$23:$D$26,MONTH(I$2)/3)} -> 0.35 | J5: {=INDEX(Assumptions!$D$23:$D$26,MONTH(J$2)/3)} -> 0.2 | ... CD5: {=INDEX(Assumptions!$D$23:$D$26,MONTH(CD$2)/3)} -> 0.2
A6: CFADS (k) | C6: =C4*C5*Assumptions!$D$18/1000 -> 8000 | D6: =D4*D5*Assumptions!$D$18/1000 -> 10200 | E6: =E4*E5*Assumptions!$D$18/1000 -> 14280 | F6: =F4*F5*Assumptions!$D$18/1000 -> 8160 | G6: =G4*G5*Assumptions!$D$18/1000 -> 8160 | H6: =H4*H5*Assumptions!$D$18/1000 -> 10404 | I6: =I4*I5*Assumptions!$D$18/1000 -> 14565.6 | J6: =J4*J5*Assumptions!$D$18/1000 -> 8323.2 | ... CD6: =CD4*CD5*Assumptions!$D$18/1000 -> 11887.579
A8: SOFR (%) | C8: =IFERROR(VLOOKUP(C$1,Assumptions!$F$33:$H$38,3,0),B8+INDEX(Assumptions!$J$33:$J$38,MATCH(C$1,Assumptions!$F$33:$F$38,1))) -> 0.005 | D8: =IFERROR(VLOOKUP(D$1,Assumptions!$F$33:$H$38,3,0),C8+INDEX(Assumptions!$J$33:$J$38,MATCH(D$1,Assumptions!$F$33:$F$38,1))) -> 0.0067 | E8: =IFERROR(VLOOKUP(E$1,Assumptions!$F$33:$H$38,3,0),D8+INDEX(Assumptions!$J$33:$J$38,MATCH(E$1,Assumptions!$F$33:$F$38,1))) -> 0.007525 | F8: =IFERROR(VLOOKUP(F$1,Assumptions!$F$33:$H$38,3,0),E8+INDEX(Assumptions!$J$33:$J$38,MATCH(F$1,Assumptions!$F$33:$F$38,1))) -> 0.00835 | G8: =IFERROR(VLOOKUP(G$1,Assumptions!$F$33:$H$38,3,0),F8+INDEX(Assumptions!$J$33:$J$38,MATCH(G$1,Assumptions!$F$33:$F$38,1))) -> 0.009175 | H8: =IFERROR(VLOOKUP(H$1,Assumptions!$F$33:$H$38,3,0),G8+INDEX(Assumptions!$J$33:$J$38,MATCH(H$1,Assumptions!$F$33:$F$38,1))) -> 0.01 | I8: =IFERROR(VLOOKUP(I$1,Assumptions!$F$33:$H$38,3,0),H8+INDEX(Assumptions!$J$33:$J$38,MATCH(I$1,Assumptions!$F$33:$F$38,1))) -> 0.0125 | J8: =IFERROR(VLOOKUP(J$1,Assumptions!$F$33:$H$38,3,0),I8+INDEX(Assumptions!$J$33:$J$38,MATCH(J$1,Assumptions!$F$33:$F$38,1))) -> 0.015 | ... CD8: =IFERROR(VLOOKUP(CD$1,Assumptions!$F$33:$H$38,3,0),CC8+INDEX(Assumptions!$J$33:$J$38,MATCH(CD$1,Assumptions!$F$33:$F$38,1))) -> 0.035
A10: Senior debt
A12: Opening | C12: =Assumptions!D32/1000 -> 250000 | D12: =C15 -> 245833.33 | E12: =D15 -> 241666.67 | F12: =E15 -> 235471.72 | G12: =F15 -> 231305.05 | H12: =G15 -> 227138.39 | I12: =H15 -> 222971.72 | J12: =I15 -> 216738.88 | K12: =J15 -> 212572.21 | ... CD12: =CC15 -> 0
A13: Mand repay | C13: =-MIN(MAX(C21:C22),C12) -> -4166.6667 | D13: =-MIN(MAX(D21:D22),D12) -> -4166.6667 | E13: =-MIN(MAX(E21:E22),E12) -> -6194.9479 | F13: =-MIN(MAX(F21:F22),F12) -> -4166.6667 | G13: =-MIN(MAX(G21:G22),G12) -> -4166.6667 | H13: =-MIN(MAX(H21:H22),H12) -> -4166.6667 | I13: =-MIN(MAX(I21:I22),I12) -> -6232.8401 | J13: =-MIN(MAX(J21:J22),J12) -> -4166.6667 | ... CD13: =-MIN(MAX(CD21:CD22),CD12) -> 0
A14: Accel repay | C14: =C60 -> 0 | D14: =D60 -> 0 | E14: =E60 -> 0 | F14: =F60 -> 0 | G14: =G60 -> 0 | H14: =H60 -> 0 | I14: =I60 -> 0 | J14: =J60 -> 0 | ... CD14: =CD60 -> 0
A15: closing | C15: =SUM(C12:C14) -> 245833.33 | D15: =SUM(D12:D14) -> 241666.67 | E15: =SUM(E12:E14) -> 235471.72 | F15: =SUM(F12:F14) -> 231305.05 | G15: =SUM(G12:G14) -> 227138.39 | H15: =SUM(H12:H14) -> 222971.72 | I15: =SUM(I12:I14) -> 216738.88 | J15: =SUM(J12:J14) -> 212572.21 | ... CD15: =SUM(CD12:CD14) -> 0
A17: Int rate | C17: =C8+Assumptions!$D$34 -> 0.03 | D17: =D8+Assumptions!$D$34 -> 0.0317 | E17: =E8+Assumptions!$D$34 -> 0.032525 | F17: =F8+Assumptions!$D$34 -> 0.03335 | G17: =G8+Assumptions!$D$34 -> 0.034175 | H17: =H8+Assumptions!$D$34 -> 0.035 | I17: =I8+Assumptions!$D$34 -> 0.0375 | J17: =J8+Assumptions!$D$34 -> 0.04 | ... CD17: =CD8+Assumptions!$D$34 -> 0.06
A18: Interest | C18: =C12*C17/4 -> 1875 | D18: =D12*D17/4 -> 1948.2292 | E18: =E12*E17/4 -> 1965.0521 | F18: =F12*F17/4 -> 1963.2455 | G18: =G12*G17/4 -> 1976.2125 | H18: =H12*H17/4 -> 1987.4609 | I18: =I12*I17/4 -> 2090.3599 | J18: =J12*J17/4 -> 2167.3888 | ... CD18: =CD12*CD17/4 -> 0
A20: Target DSCR | C20: =C6/Assumptions!$D$33 -> 4571.4286 | D20: =D6/Assumptions!$D$33 -> 5828.5714 | E20: =E6/Assumptions!$D$33 -> 8160 | F20: =F6/Assumptions!$D$33 -> 4662.8571 | G20: =G6/Assumptions!$D$33 -> 4662.8571 | H20: =H6/Assumptions!$D$33 -> 5945.1429 | I20: =I6/Assumptions!$D$33 -> 8323.2 | J20: =J6/Assumptions!$D$33 -> 4756.1143 | ... CD20: =CD6/Assumptions!$D$33 -> 6792.9024
A21: Mand (by DSCR) | C21: =C20-C18 -> 2696.4286 | D21: =D20-D18 -> 3880.3423 | E21: =E20-E18 -> 6194.9479 | F21: =F20-F18 -> 2699.6117 | G21: =G20-G18 -> 2686.6446 | H21: =H20-H18 -> 3957.682 | I21: =I20-I18 -> 6232.8401 | J21: =J20-J18 -> 2588.7255 | ... CD21: =CD20-CD18 -> 6792.9024
A22: Mand (by term) | C22: =Assumptions!$D$32/Assumptions!$D$35/4/1000 -> 4166.6667 | D22: =Assumptions!$D$32/Assumptions!$D$35/4/1000 -> 4166.6667 | E22: =Assumptions!$D$32/Assumptions!$D$35/4/1000 -> 4166.6667 | F22: =Assumptions!$D$32/Assumptions!$D$35/4/1000 -> 4166.6667 | G22: =Assumptions!$D$32/Assumptions!$D$35/4/1000 -> 4166.6667 | H22: =Assumptions!$D$32/Assumptions!$D$35/4/1000 -> 4166.6667 | I22: =Assumptions!$D$32/Assumptions!$D$35/4/1000 -> 4166.6667 | J22: =Assumptions!$D$32/Assumptions!$D$35/4/1000 -> 4166.6667 | ... CD22: =Assumptions!$D$32/Assumptions!$D$35/4/1000 -> 4166.6667
A25: Subordinate debt
A27: Remaining periods | C27: =Assumptions!D41*4 -> 70 | D27: =MAX(C27-1,0) -> 69 | E27: =MAX(D27-1,0) -> 68 | F27: =MAX(E27-1,0) -> 67 | G27: =MAX(F27-1,0) -> 66 | H27: =MAX(G27-1,0) -> 65 | I27: =MAX(H27-1,0) -> 64 | J27: =MAX(I27-1,0) -> 63 | K27: =MAX(J27-1,0) -> 62 | ... CD27: =MAX(CC27-1,0) -> 0
A29: Opening | C29: =Assumptions!$D$39/1000 -> 70000 | D29: =C32 -> 69000 | E29: =D32 -> 67287.499 | F29: =E32 -> 64683.155 | G29: =F32 -> 63712.308 | H29: =G32 -> 62746.97 | I29: =H32 -> 61635.36 | J29: =I32 -> 59331.01 | K29: =J32 -> 58389.248 | ... CD29: =CC32 -> 0
A30: Mand Repay | C30: =-IF(C29=0,0,C29/C27) -> -1000 | D30: =-IF(D29=0,0,D29/D27) -> -1000 | E30: =-IF(E29=0,0,E29/E27) -> -989.52205 | F30: =-IF(F29=0,0,F29/F27) -> -965.42022 | G30: =-IF(G29=0,0,G29/G27) -> -965.338 | H30: =-IF(H29=0,0,H29/H27) -> -965.338 | I30: =-IF(I29=0,0,I29/I27) -> -963.0525 | J30: =-IF(J29=0,0,J29/J27) -> -941.76207 | ... CD30: =-IF(CD29=0,0,CD29/CD27) -> 0
A31: Acc repay | C31: =C59 -> 0 | D31: =D59 -> -712.50079 | E31: =E59 -> -1614.8224 | F31: =F59 -> -5.4265577 | G31: =G59 -> 0 | H31: =H59 -> -146.27211 | I31: =I59 -> -1341.297 | J31: =J59 -> 0 | ... CD31: =CD59 -> 0
A32: Closing | C32: =SUM(C29:C31) -> 69000 | D32: =SUM(D29:D31) -> 67287.499 | E32: =SUM(E29:E31) -> 64683.155 | F32: =SUM(F29:F31) -> 63712.308 | G32: =SUM(G29:G31) -> 62746.97 | H32: =SUM(H29:H31) -> 61635.36 | I32: =SUM(I29:I31) -> 59331.01 | J32: =SUM(J29:J31) -> 58389.248 | ... CD32: =SUM(CD29:CD31) -> 0
A34: Int Rate | C34: =Assumptions!$D$40 -> 0.065 | D34: =Assumptions!$D$40 -> 0.065 | E34: =Assumptions!$D$40 -> 0.065 | F34: =Assumptions!$D$40 -> 0.065 | G34: =IFERROR(VLOOKUP(G35,Assumptions!$F$43:$H$47,COLUMNS(Assumptions!$F$43:$H$47),1),0) -> 0.125 | H34: =IFERROR(VLOOKUP(H35,Assumptions!$F$43:$H$47,COLUMNS(Assumptions!$F$43:$H$47),1),0) -> 0.125 | I34: =IFERROR(VLOOKUP(I35,Assumptions!$F$43:$H$47,COLUMNS(Assumptions!$F$43:$H$47),1),0) -> 0.125 | J34: =IFERROR(VLOOKUP(J35,Assumptions!$F$43:$H$47,COLUMNS(Assumptions!$F$43:$H$47),1),0) -> 0.125 | K34: =IFERROR(VLOOKUP(K35,Assumptions!$F$43:$H$47,COLUMNS(Assumptions!$F$43:$H$47),1),0) -> 0.125 | L34: =IFERROR(VLOOKUP(L35,Assumptions!$F$43:$H$47,COLUMNS(Assumptions!$F$43:$H$47),1),0) -> 0.125 | M34: =IFERROR(VLOOKUP(M35,Assumptions!$F$43:$H$47,COLUMNS(Assumptions!$F$43:$H$47),1),0) -> 0.125 | N34: =IFERROR(VLOOKUP(N35,Assumptions!$F$43:$H$47,COLUMNS(Assumptions!$F$43:$H$47),1),0) -> 0.125 | ... BR34: =IFERROR(VLOOKUP(BR35,Assumptions!$F$43:$H$47,COLUMNS(Assumptions!$F$43:$H$47),1),0) -> 0.05 | BT34: =IFERROR(VLOOKUP(BT35,Assumptions!$F$43:$H$47,COLUMNS(Assumptions!$F$43:$H$47),1),0) -> 0.05 | BU34: =IFERROR(VLOOKUP(BU35,Assumptions!$F$43:$H$47,COLUMNS(Assumptions!$F$43:$H$47),1),0) -> 0.05 | BV34: =IFERROR(VLOOKUP(BV35,Assumptions!$F$43:$H$47,COLUMNS(Assumptions!$F$43:$H$47),1),0) -> 0.05 | BW34: =IFERROR(VLOOKUP(BW35,Assumptions!$F$43:$H$47,COLUMNS(Assumptions!$F$43:$H$47),1),0) -> 0.05 | BX34: =IFERROR(VLOOKUP(BX35,Assumptions!$F$43:$H$47,COLUMNS(Assumptions!$F$43:$H$47),1),0) -> 0.05 | BY34: =IFERROR(VLOOKUP(BY35,Assumptions!$F$43:$H$47,COLUMNS(Assumptions!$F$43:$H$47),1),0) -> 0.05 | BZ34: =IFERROR(VLOOKUP(BZ35,Assumptions!$F$43:$H$47,COLUMNS(Assumptions!$F$43:$H$47),1),0) -> 0.05 | CA34: =IFERROR(VLOOKUP(CA35,Assumptions!$F$43:$H$47,COLUMNS(Assumptions!$F$43:$H$47),1),0) -> 0.05 | ... CD34: =IFERROR(VLOOKUP(CD35,Assumptions!$F$43:$H$47,COLUMNS(Assumptions!$F$43:$H$47),1),0) -> 0.05
A35: Debt/EBITDA | C35: N/A | D35: N/A | E35: N/A | F35: N/A | G35: =(G40+G29+G12)/SUM(C6:F6) -> 7.2592854 | H35: =(H40+H29+H12)/SUM(D6:G6) -> 7.1280535 | I35: =(I40+I29+I12)/SUM(E6:H6) -> 6.9409589 | J35: =(J40+J29+J12)/SUM(F6:I6) -> 6.6861846 | K35: =(K40+K29+K12)/SUM(G6:J6) -> 6.5560872 | L35: =(L40+L29+L12)/SUM(H6:K6) -> 6.4289183 | M35: =(M40+M29+M12)/SUM(I6:L6) -> 6.2430941 | N35: =(N40+N29+N12)/SUM(J6:M6) -> 5.9936486 | ... CD35: =(CD40+CD29+CD12)/SUM(BZ6:CC6) -> 0
A36: Interest | C36: =C29*C34/4 -> 1137.5 | D36: =D29*D34/4 -> 1121.25 | E36: =E29*E34/4 -> 1093.4219 | F36: =F29*F34/4 -> 1051.1013 | G36: =G29*G34/4 -> 1991.0096 | H36: =H29*H34/4 -> 1960.8428 | I36: =I29*I34/4 -> 1926.105 | J36: =J29*J34/4 -> 1854.0941 | ... CD36: =CD29*CD34/4 -> 0
A38: Revolver
A40: Opening | C40: =Assumptions!D44 -> 0 | D40: =C43 -> 179.16667 | E40: =D43 -> 0 | F40: =E43 -> 0 | G40: =F43 -> 0 | H40: =G43 -> 939.22683 | I40: =H43 -> 0 | J40: =I43 -> 0 | K40: =J43 -> 806.71159 | ... CD40: =CC43 -> 0
A41: Drawdown | C41: =C55 -> 179.16667 | D41: =D55 -> 0 | E41: =E55 -> 0 | F41: =F55 -> 0 | G41: =G55 -> 939.22683 | H41: =H55 -> 0 | I41: =I55 -> 0 | J41: =J55 -> 806.71159 | ... CD41: =CD55 -> 0
A42: Repayment | C42: =C56 -> 0 | D42: =D56 -> -179.16667 | E42: =E56 -> 0 | F42: =F56 -> 0 | G42: =G56 -> 0 | H42: =H56 -> -939.22683 | I42: =I56 -> 0 | J42: =J56 -> 0 | ... CD42: =CD56 -> 0
A43: Closing | C43: =SUM(C40:C42) -> 179.16667 | D43: =SUM(D40:D42) -> 0 | E43: =SUM(E40:E42) -> 0 | F43: =SUM(F40:F42) -> 0 | G43: =SUM(G40:G42) -> 939.22683 | H43: =SUM(H40:H42) -> 0 | I43: =SUM(I40:I42) -> 0 | J43: =SUM(J40:J42) -> 806.71159 | ... CD43: =SUM(CD40:CD42) -> 0
A45: Interest rate | C45: =C8+Assumptions!$D$46 -> 0.075 | D45: =D8+Assumptions!$D$46 -> 0.0767 | E45: =E8+Assumptions!$D$46 -> 0.077525 | F45: =F8+Assumptions!$D$46 -> 0.07835 | G45: =G8+Assumptions!$D$46 -> 0.079175 | H45: =H8+Assumptions!$D$46 -> 0.08 | I45: =I8+Assumptions!$D$46 -> 0.0825 | J45: =J8+Assumptions!$D$46 -> 0.085 | ... CD45: =CD8+Assumptions!$D$46 -> 0.105
A46: Interest rate | C46: =C40*C45/4 -> 0 | D46: =D40*D45/4 -> 3.4355208 | E46: =E40*E45/4 -> 0 | F46: =F40*F45/4 -> 0 | G46: =G40*G45/4 -> 0 | H46: =H40*H45/4 -> 18.784537 | I46: =I40*I45/4 -> 0 | J46: =J40*J45/4 -> 0 | ... CD46: =CD40*CD45/4 -> 0
A48: Waterfall
A50: CFADS | C50: =C6 -> 8000 | D50: =D6 -> 10200 | E50: =E6 -> 14280 | F50: =F6 -> 8160 | G50: =G6 -> 8160 | H50: =H6 -> 10404 | I50: =I6 -> 14565.6 | J50: =J6 -> 8323.2 | ... CD50: =CD6 -> 11887.579
A51: Interest | C51: =-C46-C36-C18 -> -3012.5 | D51: =-D46-D36-D18 -> -3072.9147 | E51: =-E46-E36-E18 -> -3058.4739 | F51: =-F46-F36-F18 -> -3014.3467 | G51: =-G46-G36-G18 -> -3967.2222 | H51: =-H46-H36-H18 -> -3967.0882 | I51: =-I46-I36-I18 -> -4016.4649 | J51: =-J46-J36-J18 -> -4021.4829 | ... CD51: =-CD46-CD36-CD18 -> 0
A52: Mand Repayment | C52: =C30+C13 -> -5166.6667 | D52: =D30+D13 -> -5166.6667 | E52: =E30+E13 -> -7184.47 | F52: =F30+F13 -> -5132.0869 | G52: =G30+G13 -> -5132.0047 | H52: =H30+H13 -> -5132.0047 | I52: =I30+I13 -> -7195.8926 | J52: =J30+J13 -> -5108.4287 | ... CD52: =CD30+CD13 -> 0
A53: Cash pre revolver | C53: =SUM(C50:C52) -> -179.16667 | D53: =SUM(D50:D52) -> 1960.4186 | E53: =SUM(E50:E52) -> 4037.0561 | F53: =SUM(F50:F52) -> 13.566394 | G53: =SUM(G50:G52) -> -939.22683 | H53: =SUM(H50:H52) -> 1304.9071 | I53: =SUM(I50:I52) -> 3353.2425 | J53: =SUM(J50:J52) -> -806.71159 | ... CD53: =SUM(CD50:CD52) -> 11887.579
A54: Avail revolver | C54: =Assumptions!$D$45/1000-C40 -> 5000 | D54: =Assumptions!$D$45/1000-D40 -> 4820.8333 | E54: =Assumptions!$D$45/1000-E40 -> 5000 | F54: =Assumptions!$D$45/1000-F40 -> 5000 | G54: =Assumptions!$D$45/1000-G40 -> 5000 | H54: =Assumptions!$D$45/1000-H40 -> 4060.7732 | I54: =Assumptions!$D$45/1000-I40 -> 5000 | J54: =Assumptions!$D$45/1000-J40 -> 5000 | ... CD54: =Assumptions!$D$45/1000-CD40 -> 5000
A55: Revolver draw | C55: =IF(C53<0,MIN(-C53,C54),0) -> 179.16667 | D55: =IF(D53<0,MIN(-D53,D54),0) -> 0 | E55: =IF(E53<0,MIN(-E53,E54),0) -> 0 | F55: =IF(F53<0,MIN(-F53,F54),0) -> 0 | G55: =IF(G53<0,MIN(-G53,G54),0) -> 939.22683 | H55: =IF(H53<0,MIN(-H53,H54),0) -> 0 | I55: =IF(I53<0,MIN(-I53,I54),0) -> 0 | J55: =IF(J53<0,MIN(-J53,J54),0) -> 806.71159 | ... CD55: =IF(CD53<0,MIN(-CD53,CD54),0) -> 0
A56: Revolver repay | C56: =IF(C53>0,-MIN(C40,C53),0) -> 0 | D56: =IF(D53>0,-MIN(D40,D53),0) -> -179.16667 | E56: =IF(E53>0,-MIN(E40,E53),0) -> 0 | F56: =IF(F53>0,-MIN(F40,F53),0) -> 0 | G56: =IF(G53>0,-MIN(G40,G53),0) -> 0 | H56: =IF(H53>0,-MIN(H40,H53),0) -> -939.22683 | I56: =IF(I53>0,-MIN(I40,I53),0) -> 0 | J56: =IF(J53>0,-MIN(J40,J53),0) -> 0 | ... XFD56: =IF(XFD53>0,-MIN(XFD40,XFD53),0) -> 0
...
